Workbook

Sheet How to use
A1: AFK Slayer — Balance Cockpit
A3: What this is for
A4: Set how long each rank / gear / hire / unlock SHOULD take, and how strong upgrades SHOULD feel. Other tabs compare the live (or proposed) numbers to those targets and flag Too fast / Too slow / Too strong / Too weak.
A6: How to work it (repeat this loop)
A7: 1. Open Targets — fill the yellow “I want…” times and power budgets. That tab is the source of truth for feel.
A8: 2. Open Journey — read the play timeline. Green = on pace. Yellow = arrives too early (power spike risk). Red = arrives too late (feel stuck).
A9: 3. Open Ranks — tweak XP thresholds (or the curve knobs) until hours-to-rank match your Targets.
A10: 4. Open Upgrades — each row shows gate time, cost, effect, and a power score. Compare to the budget for that track. Flag column tells you Strong / Weak / OK.
A11: 5. Open Monsters & Mastery — keep Undercroft (and later areas) distinct without one contract printing gold/XP.
A12: 6. When a yellow number changes, blue cells recalculate. When you lock a change, tell Game Designer / New Bot to ship it into the game.
A14: Colors
A15: Yellow = you edit · Blue = auto · Green banner/result = on target · Gold/Yellow flag = too fast or too strong · Red flag = too slow or too weak
... A19: Working title in code folder is still contract-board; player-facing name is AFK Slayer.

Sheet Targets
A1: TARGETS — what “good pacing” means (edit yellow)
A2: These are design goals, not live code. Journey / Ranks / Upgrades compare against this page.
A4: A · Rank time goals (hours of play from a fresh save)
A5: Rank | B5: Name | C5: Target hours from start | D5: Tolerance ± hours | E5: Notes
A6: 0 | B6: Recruit | C6: 0 | D6: 0.25 | E6: Live game ranks 0–9
A7: 1 | B7: Runner | C7: 0.25 | D7: 0.25 | E7: Live game ranks 0–9
A8: 2 | B8: Tracker | C8: 1 | D8: 0.25 | E8: Live game ranks 0–9
A9: 3 | B9: Hunter | C9: 2.5 | D9: 0.25 | E9: Live game ranks 0–9
A10: 4 | B10: Veteran | C10: 5 | D10: 1 | E10: Live game ranks 0–9
A11: 5 | B11: Warden | C11: 9 | D11: 1 | E11: Live game ranks 0–9
A12: 6 | B12: Guildhand | C12: 14 | D12: 1 | E12: Live game ranks 0–9
A13: 7 | B13: Marshal | C13: 22 | D13: 1 | E13: Live game ranks 0–9
A14: 8 | B14: Archivist | C14: 32 | D14: 1 | E14: Live game ranks 0–9
A15: 9 | B15: Charter Lord | C15: 45 | D15: 1 | E15: Live game ranks 0–9
A16: 10 | B16: High Charter | C16: 60 | D16: 5 | E16: Proposed late ranks
A17: 11 | B17: Vault Hand | C17: 80 | D17: 5 | E17: Proposed late ranks
... A26: 20 | B26: Legend | C26: 500 | D26: 5 | E26: Proposed late ranks
A28: B · Milestone time goals (minutes of play)
A29: Milestone | B29: Live gate (min) | C29: Target (min) | D29: Tolerance ± min | E29: Why it matters
A30: Iron Blade | B30: 10 | C30: 10 | D30: 2 | E30: First gear buy — should feel earned, not wall
A31: Steel Blade | B31: 15 | C31: 15 | D31: 3
A32: Bolt Focus | B32: 8 | C32: 8 | D32: 2 | E32: Teaches bolt upgrades early
A33: Bolt Pierce | B33: 15 | C33: 12 | D33: 3 | E33: Must land before Infernal Mages feel bad
A34: Hire Briar | B34: 15 | C34: 15 | D34: 3 | E34: First hunter — independent power track
A35: Unlock Crits | B35: 20 | C35: 20 | D35: 4
A36: Mithril Blade | B36: 22.5 | C36: 22 | D36: 4
A37: Hire Quill | B37: 90 | C37: 75 | D37: 15 | E37: Softens Banshee aim rage if earlier
A38: Adamant Blade | B38: 33.75 | C38: 35 | D38: 5
A39: Hire Moss | B39: 180 | C39: 180 | D39: 20
A40: Dragon Blade | B40: 75.9 | C40: 80 | D40: 10
A41: Hire Ember | B41: 300 | C41: 300 | D41: 30
A44: C · Power budgets (per upgrade level — higher = stronger allowed)
A45: Track | B45: Max power score / level (budget) | C45: OP if over by % | D45: UP if under by % | E45: Notes
A46: Combat | B46: 25 | C46: 0.25 | D46: 0.25 | E46: Crits, pierce, bolt focus, idle power
A47: Gear | B47: 20 | C47: 0.25 | D47: 0.25 | E47: Blade ladder — big idlePower jumps
A48: Company | B48: 30 | C48: 0.25 | D48: 0.3 | E48: Hunter damage/speed — easy to go OP
A49: Camp | B49: 12 | C49: 0.3 | D49: 0.3 | E49: Food / offline / luck — support track
A50: Mastery perk | B50: 18 | C50: 0.3 | D50: 0.3 | E50: Per-monster mastery at 3/6/10
A53: D · Economy pace knobs (used by Monsters + Journey estimates)
A54: Assumed total DPS (early) | B54: 17.5 | C54: Player ~10 + hunters ~7.5. Change as you simulate later gear.
...

Sheet Journey
A1: JOURNEY — play timeline vs your Targets
A2: Each row is something the player unlocks. Live gate comes from the game. Target comes from Targets tab. Status: ON PACE / TOO EARLY (power spike) / TOO LATE (feels stuck).
A4: Play min | B4: Unlock / event | C4: Live gate (min) | D4: Your target (min) | E4: Delta (live−target) | F4: Status | G4: Track | H4: Designer note
A5: 8 | B5: Bolt Focus | C5: 8 | D5: =Targets!C32 | E5: =C5-D5 | F5: =IF(ABS(E5)<=Targets!D32,"ON PACE",IF(E5<0,"TOO EARLY","TOO LATE")) | G5: Combat | H5: Teaches bolt upgrades early
A6: 10 | B6: Iron Blade | C6: 10 | D6: =Targets!C30 | E6: =C6-D6 | F6: =IF(ABS(E6)<=Targets!D30,"ON PACE",IF(E6<0,"TOO EARLY","TOO LATE")) | G6: Gear | H6: First gear buy — should feel earned, not wall
A7: 15 | B7: Steel Blade | C7: 15 | D7: =Targets!C31 | E7: =C7-D7 | F7: =IF(ABS(E7)<=Targets!D31,"ON PACE",IF(E7<0,"TOO EARLY","TOO LATE")) | G7: Gear
A8: 15 | B8: Bolt Pierce | C8: 15 | D8: =Targets!C33 | E8: =C8-D8 | F8: =IF(ABS(E8)<=Targets!D33,"ON PACE",IF(E8<0,"TOO EARLY","TOO LATE")) | G8: Combat | H8: Must land before Infernal Mages feel bad
A9: 15 | B9: Hire Briar | C9: 15 | D9: =Targets!C34 | E9: =C9-D9 | F9: =IF(ABS(E9)<=Targets!D34,"ON PACE",IF(E9<0,"TOO EARLY","TOO LATE")) | G9: Company | H9: First hunter — independent power track
A10: 15 | B10: Rank 1: Runner | C10: =Targets!C7*60 | D10: =Targets!C7*60 | E10: =C10-D10 | F10: =IF(ABS(E10)<=Targets!D7*60,"ON PACE",IF(E10<0,"TOO EARLY","TOO LATE")) | G10: Rank | H10: Target hours × 60
A11: 20 | B11: Unlock Crits | C11: 20 | D11: =Targets!C35 | E11: =C11-D11 | F11: =IF(ABS(E11)<=Targets!D35,"ON PACE",IF(E11<0,"TOO EARLY","TOO LATE")) | G11: Combat
A12: 22.5 | B12: Mithril Blade | C12: 22.5 | D12: =Targets!C36 | E12: =C12-D12 | F12: =IF(ABS(E12)<=Targets!D36,"ON PACE",IF(E12<0,"TOO EARLY","TOO LATE")) | G12: Gear
A13: 33.75 | B13: Adamant Blade | C13: 33.75 | D13: =Targets!C38 | E13: =C13-D13 | F13: =IF(ABS(E13)<=Targets!D38,"ON PACE",IF(E13<0,"TOO EARLY","TOO LATE")) | G13: Gear
A14: 60 | B14: Rank 2: Tracker | C14: =Targets!C8*60 | D14: =Targets!C8*60 | E14: =C14-D14 | F14: =IF(ABS(E14)<=Targets!D8*60,"ON PACE",IF(E14<0,"TOO EARLY","TOO LATE")) | G14: Rank | H14: Target hours × 60
A15: 75.9 | B15: Dragon Blade | C15: 75.9 | D15: =Targets!C40 | E15: =C15-D15 | F15: =IF(ABS(E15)<=Targets!D40,"ON PACE",IF(E15<0,"TOO EARLY","TOO LATE")) | G15: Gear
A16: 90 | B16: Hire Quill | C16: 90 | D16: =Targets!C37 | E16: =C16-D16 | F16: =IF(ABS(E16)<=Targets!D37,"ON PACE",IF(E16<0,"TOO EARLY","TOO LATE")) | G16: Company | H16: Softens Banshee aim rage if earlier
A17: 150 | B17: Rank 3: Hunter | C17: =Targets!C9*60 | D17: =Targets!C9*60 | E17: =C17-D17 | F17: =IF(ABS(E17)<=Targets!D9*60,"ON PACE",IF(E17<0,"TOO EARLY","TOO LATE")) | G17: Rank | H17: Target hours × 60
A18: 180 | B18: Hire Moss | C18: 180 | D18: =Targets!C39 | E18: =C18-D18 | F18: =IF(ABS(E18)<=Targets!D39,"ON PACE",IF(E18<0,"TOO EARLY","TOO LATE")) | G18: Company
A19: 300 | B19: Hire Ember | C19: 300 | D19: =Targets!C41 | E19: =C19-D19 | F19: =IF(ABS(E19)<=Targets!D41,"ON PACE",IF(E19<0,"TOO EARLY","TOO LATE")) | G19: Company
A20: 540 | B20: Rank 5: Warden | C20: =Targets!C11*60 | D20: =Targets!C11*60 | E20: =C20-D20 | F20: =IF(ABS(E20)<=Targets!D11*60,"ON PACE",IF(E20<0,"TOO EARLY","TOO LATE")) | G20: Rank | H20: Target hours × 60
A21: 1320 | B21: Rank 7: Marshal | C21: =Targets!C13*60 | D21: =Targets!C13*60 | E21: =C21-D21 | F21: =IF(ABS(E21)<=Targets!D13*60,"ON PACE",IF(E21<0,"TOO EARLY","TOO LATE")) | G21: Rank | H21: Target hours × 60
A22: 2700 | B22: Rank 9: Charter Lord | C22: =Targets!C15*60 | D22: =Targets!C15*60 | E22: =C22-D22 | F22: =IF(ABS(E22)<=Targets!D15*60,"ON PACE",IF(E22<0,"TOO EARLY","TOO LATE")) | G22: Rank | H22: Target hours × 60
A24: How to read: TOO EARLY = players get this power before you wanted (risk OP). TOO LATE = wall / boredom. Adjust Targets or the live gate (tell New Bot).

Sheet Ranks
A1: RANKS — XP curve vs target hours
A2: Edit yellow XP thresholds (or curve knobs). Hours use Targets!B56 XP/hour. Status compares to Targets hours.
A4: Curve XP 0→1 | B4: 50
A5: Curve growth | B5: 1.45 | C5: Optional helper — paste =ROUND($B$4*$B$5^A8,0) into late ranks if you want a smooth curve.
A7: Rank | B7: Name | C7: XP to reach | D7: XP this level-up | E7: Hours from start (calc) | F7: Target hours | G7: Delta hours | H7: Status | I7: Sessions @ target session | J7: Notes
A8: 0 | B8: =Targets!B6 | C8: 0 | D8: =C9-C8 | E8: =IF(Targets!$B$56<=0,0,C8/Targets!$B$56) | F8: =Targets!C6 | G8: =E8-F8 | H8: =IF(ABS(G8)<=Targets!D6,"ON PACE",IF(G8<0,"TOO FAST","TOO SLOW")) | I8: =IF(Targets!$B$57<=0,0,E8*60/Targets!$B$57)
A9: 1 | B9: =Targets!B7 | C9: 50 | D9: =C10-C9 | E9: =IF(Targets!$B$56<=0,0,C9/Targets!$B$56) | F9: =Targets!C7 | G9: =E9-F9 | H9: =IF(ABS(G9)<=Targets!D7,"ON PACE",IF(G9<0,"TOO FAST","TOO SLOW")) | I9: =IF(Targets!$B$57<=0,0,E9*60/Targets!$B$57)
A10: 2 | B10: =Targets!B8 | C10: 150 | D10: =C11-C10 | E10: =IF(Targets!$B$56<=0,0,C10/Targets!$B$56) | F10: =Targets!C8 | G10: =E10-F10 | H10: =IF(ABS(G10)<=Targets!D8,"ON PACE",IF(G10<0,"TOO FAST","TOO SLOW")) | I10: =IF(Targets!$B$57<=0,0,E10*60/Targets!$B$57)
A11: 3 | B11: =Targets!B9 | C11: 350 | D11: =C12-C11 | E11: =IF(Targets!$B$56<=0,0,C11/Targets!$B$56) | F11: =Targets!C9 | G11: =E11-F11 | H11: =IF(ABS(G11)<=Targets!D9,"ON PACE",IF(G11<0,"TOO FAST","TOO SLOW")) | I11: =IF(Targets!$B$57<=0,0,E11*60/Targets!$B$57)
A12: 4 | B12: =Targets!B10 | C12: 700 | D12: =C13-C12 | E12: =IF(Targets!$B$56<=0,0,C12/Targets!$B$56) | F12: =Targets!C10 | G12: =E12-F12 | H12: =IF(ABS(G12)<=Targets!D10,"ON PACE",IF(G12<0,"TOO FAST","TOO SLOW")) | I12: =IF(Targets!$B$57<=0,0,E12*60/Targets!$B$57)
A13: 5 | B13: =Targets!B11 | C13: 1300 | D13: =C14-C13 | E13: =IF(Targets!$B$56<=0,0,C13/Targets!$B$56) | F13: =Targets!C11 | G13: =E13-F13 | H13: =IF(ABS(G13)<=Targets!D11,"ON PACE",IF(G13<0,"TOO FAST","TOO SLOW")) | I13: =IF(Targets!$B$57<=0,0,E13*60/Targets!$B$57)
A14: 6 | B14: =Targets!B12 | C14: 2200 | D14: =C15-C14 | E14: =IF(Targets!$B$56<=0,0,C14/Targets!$B$56) | F14: =Targets!C12 | G14: =E14-F14 | H14: =IF(ABS(G14)<=Targets!D12,"ON PACE",IF(G14<0,"TOO FAST","TOO SLOW")) | I14: =IF(Targets!$B$57<=0,0,E14*60/Targets!$B$57)
A15: 7 | B15: =Targets!B13 | C15: 3600 | D15: =C16-C15 | E15: =IF(Targets!$B$56<=0,0,C15/Targets!$B$56) | F15: =Targets!C13 | G15: =E15-F15 | H15: =IF(ABS(G15)<=Targets!D13,"ON PACE",IF(G15<0,"TOO FAST","TOO SLOW")) | I15: =IF(Targets!$B$57<=0,0,E15*60/Targets!$B$57)
A16: 8 | B16: =Targets!B14 | C16: 5500 | D16: =C17-C16 | E16: =IF(Targets!$B$56<=0,0,C16/Targets!$B$56) | F16: =Targets!C14 | G16: =E16-F16 | H16: =IF(ABS(G16)<=Targets!D14,"ON PACE",IF(G16<0,"TOO FAST","TOO SLOW")) | I16: =IF(Targets!$B$57<=0,0,E16*60/Targets!$B$57)
A17: 9 | B17: =Targets!B15 | C17: 8000 | D17: =C18-C17 | E17: =IF(Targets!$B$56<=0,0,C17/Targets!$B$56) | F17: =Targets!C15 | G17: =E17-F17 | H17: =IF(ABS(G17)<=Targets!D15,"ON PACE",IF(G17<0,"TOO FAST","TOO SLOW")) | I17: =IF(Targets!$B$57<=0,0,E17*60/Targets!$B$57)
A18: 10 | B18: =Targets!B16 | C18: 2054 | D18: =C19-C18 | E18: =IF(Targets!$B$56<=0,0,C18/Targets!$B$56) | F18: =Targets!C16 | G18: =E18-F18 | H18: =IF(ABS(G18)<=Targets!D16,"ON PACE",IF(G18<0,"TOO FAST","TOO SLOW")) | I18: =IF(Targets!$B$57<=0,0,E18*60/Targets!$B$57)
A19: 11 | B19: =Targets!B17 | C19: 2979 | D19: =C20-C19 | E19: =IF(Targets!$B$56<=0,0,C19/Targets!$B$56) | F19: =Targets!C17 | G19: =E19-F19 | H19: =IF(ABS(G19)<=Targets!D17,"ON PACE",IF(G19<0,"TOO FAST","TOO SLOW")) | I19: =IF(Targets!$B$57<=0,0,E19*60/Targets!$B$57)
... A27: 19 | B27: =Targets!B25 | C27: 58205 | D27: =C28-C27 | E27: =IF(Targets!$B$56<=0,0,C27/Targets!$B$56) | F27: =Targets!C25 | G27: =E27-F27 | H27: =IF(ABS(G27)<=Targets!D25,"ON PACE",IF(G27<0,"TOO FAST","TOO SLOW")) | I27: =IF(Targets!$B$57<=0,0,E27*60/Targets!$B$57)
A28: 20 | B28: =Targets!B26 | C28: 84398 | D28: 0 | E28: =IF(Targets!$B$56<=0,0,C28/Targets!$B$56) | F28: =Targets!C26 | G28: =E28-F28 | H28: =IF(ABS(G28)<=Targets!D26,"ON PACE",IF(G28<0,"TOO FAST","TOO SLOW")) | I28: =IF(Targets!$B$57<=0,0,E28*60/Targets!$B$57)
A30: TOO FAST = players hit this rank sooner than you wanted (often because XP/hr is high or XP threshold is low). Raise XP in col C or lower farm rate.

Sheet Upgrades
A1: UPGRADES — power, cost, and timing (are they OP or UP?)
A2: Power score is a design heuristic (not in-game). Budget comes from Targets §C. Per-level power = score / maxLevel. Flag: OK / TOO STRONG / TOO WEAK vs that track’s budget.
A4: Track | B4: Upgrade | C4: Gate min (live) | D4: Your target min | E4: Delta | F4: Base cost | G4: Cost mult | H4: Max lv | I4: Effect / level | J4: Power score | K4: Power / level | L4: Flag | M4: Tune note
A5: Combat | B5: Idle Power | C5: 0 | D5: 0 | E5: =C5-D5 | F5: 40 | G5: 1.55 | H5: 40 | I5: idlePower +12%/lv | J5: 192 | K5: =IF(H5<=0,0,J5/H5) | L5: =IF(K5>Targets!$B$46*(1+Targets!$C$46),"TOO STRONG",IF(K5<Targets!$B$46*(1-Targets!$D$46),"TOO WEAK","OK"))
A6: Gear | B6: Bronze Blade | C6: 0 | D6: 0 | E6: =C6-D6 | F6: 0 | G6: 1 | H6: 1 | I6: idlePower +8%/lv | J6: 3.2 | K6: =IF(H6<=0,0,J6/H6) | L6: =IF(K6>Targets!$B$47*(1+Targets!$C$47),"TOO STRONG",IF(K6<Targets!$B$47*(1-Targets!$D$47),"TOO WEAK","OK"))
A7: Gear | B7: Iron Blade | C7: 10 | D7: =Targets!C30 | E7: =C7-D7 | F7: 180 | G7: 1 | H7: 1 | I7: idlePower +12%/lv | J7: 4.8 | K7: =IF(H7<=0,0,J7/H7) | L7: =IF(K7>Targets!$B$47*(1+Targets!$C$47),"TOO STRONG",IF(K7<Targets!$B$47*(1-Targets!$D$47),"TOO WEAK","OK"))
A8: Gear | B8: Steel Blade | C8: 15 | D8: =Targets!C31 | E8: =C8-D8 | F8: 450 | G8: 1 | H8: 1 | I8: idlePower +16%/lv | J8: 6.4 | K8: =IF(H8<=0,0,J8/H8) | L8: =IF(K8>Targets!$B$47*(1+Targets!$C$47),"TOO STRONG",IF(K8<Targets!$B$47*(1-Targets!$D$47),"TOO WEAK","OK"))
A9: Gear | B9: Mithril Blade | C9: 22.5 | D9: =Targets!C36 | E9: =C9-D9 | F9: 320 | G9: 1 | H9: 1 | I9: idlePower +22%/lv | J9: 8.8 | K9: =IF(H9<=0,0,J9/H9) | L9: =IF(K9>Targets!$B$47*(1+Targets!$C$47),"TOO STRONG",IF(K9<Targets!$B$47*(1-Targets!$D$47),"TOO WEAK","OK"))
A10: Gear | B10: Adamant Blade | C10: 33.75 | D10: =Targets!C38 | E10: =C10-D10 | F10: 700 | G10: 1 | H10: 1 | I10: idlePower +28%/lv | J10: 11.2 | K10: =IF(H10<=0,0,J10/H10) | L10: =IF(K10>Targets!$B$47*(1+Targets!$C$47),"TOO STRONG",IF(K10<Targets!$B$47*(1-Targets!$D$47),"TOO WEAK","OK"))
A11: Gear | B11: Rune Blade | C11: 50.625 | D11: 50.625 | E11: =C11-D11 | F11: 1500 | G11: 1 | H11: 1 | I11: idlePower +35%/lv | J11: 14 | K11: =IF(H11<=0,0,J11/H11) | L11: =IF(K11>Targets!$B$47*(1+Targets!$C$47),"TOO STRONG",IF(K11<Targets!$B$47*(1-Targets!$D$47),"TOO WEAK","OK"))
A12: Gear | B12: Dragon Blade | C12: 75.9375 | D12: =Targets!C40 | E12: =C12-D12 | F12: 3500 | G12: 1 | H12: 1 | I12: idlePower +50%/lv | J12: 20 | K12: =IF(H12<=0,0,J12/H12) | L12: =IF(K12>Targets!$B$47*(1+Targets!$C$47),"TOO STRONG",IF(K12<Targets!$B$47*(1-Targets!$D$47),"TOO WEAK","OK"))
A13: Combat | B13: Unlock Crits | C13: 20 | D13: =Targets!C35 | E13: =C13-D13 | F13: 120 | G13: 1 | H13: 1 | I13: feature=crits | J13: 30 | K13: =IF(H13<=0,0,J13/H13) | L13: =IF(K13>Targets!$B$46*(1+Targets!$C$46),"TOO STRONG",IF(K13<Targets!$B$46*(1-Targets!$D$46),"TOO WEAK","OK"))
A14: Combat | B14: Unlock Specials | C14: 25 | D14: 25 | E14: =C14-D14 | F14: 200 | G14: 1 | H14: 1 | I14: feature=specials | J14: 30 | K14: =IF(H14<=0,0,J14/H14) | L14: =IF(K14>Targets!$B$46*(1+Targets!$C$46),"TOO STRONG",IF(K14<Targets!$B$46*(1-Targets!$D$46),"TOO WEAK","OK"))
A15: Combat | B15: Bolt Focus | C15: 8 | D15: =Targets!C32 | E15: =C15-D15 | F15: 90 | G15: 1.8 | H15: 3 | I15: beamFocus +1 | J15: 0 | K15: =IF(H15<=0,0,J15/H15) | L15: =IF(K15>Targets!$B$46*(1+Targets!$C$46),"TOO STRONG",IF(K15<Targets!$B$46*(1-Targets!$D$46),"TOO WEAK","OK"))
A16: Combat | B16: Crit Power | C16: 22 | D16: 22 | E16: =C16-D16 | F16: 150 | G16: 1.7 | H16: 10 | I16: critChance +4%/lv | J16: 24 | K16: =IF(H16<=0,0,J16/H16) | L16: =IF(K16>Targets!$B$46*(1+Targets!$C$46),"TOO STRONG",IF(K16<Targets!$B$46*(1-Targets!$D$46),"TOO WEAK","OK"))
A17: Combat | B17: Special Cadence | C17: 30 | D17: 30 | E17: =C17-D17 | F17: 220 | G17: 1.75 | H17: 5 | I17: specialCadence +12%/lv | J17: 0 | K17: =IF(H17<=0,0,J17/H17) | L17: =IF(K17>Targets!$B$46*(1+Targets!$C$46),"TOO STRONG",IF(K17<Targets!$B$46*(1-Targets!$D$46),"TOO WEAK","OK"))
A18: Combat | B18: Bolt Pierce | C18: 15 | D18: =Targets!C33 | E18: =C18-D18 | F18: 180 | G18: 2.2 | H18: 2 | I18: boltPierce +1 | J18: 70 | K18: =IF(H18<=0,0,J18/H18) | L18: =IF(K18>Targets!$B$46*(1+Targets!$C$46),"TOO STRONG",IF(K18<Targets!$B$46*(1-Targets!$D$46),"TOO WEAK","OK"))
A19: Combat | B19: Bolt Bounce | C19: 20 | D19: 20 | E19: =C19-D19 | F19: 200 | G19: 2.2 | H19: 2 | I19: boltBounce +1 | J19: 60 | K19: =IF(H19<=0,0,J19/H19) | L19: =IF(K19>Targets!$B$46*(1+Targets!$C$46),"TOO STRONG",IF(K19<Targets!$B$46*(1-Targets!$D$46),"TOO WEAK","OK"))
A20: Camp | B20: Offline Cap | C20: 0 | D20: 0 | E20: =C20-D20 | F20: 80 | G20: 1.7 | H20: 20 | I20: offlineCapMin +30 | J20: 0 | K20: =IF(H20<=0,0,J20/H20) | L20: =IF(K20>Targets!$B$49*(1+Targets!$C$49),"TOO STRONG",IF(K20<Targets!$B$49*(1-Targets!$D$49),"TOO WEAK","OK"))
A21: Camp | B21: Food Efficiency | C21: 0 | D21: 0 | E21: =C21-D21 | F21: 50 | G21: 1.6 | H21: 25 | I21: foodEff +8%/lv | J21: 30 | K21: =IF(H21<=0,0,J21/H21) | L21: =IF(K21>Targets!$B$49*(1+Targets!$C$49),"TOO STRONG",IF(K21<Targets!$B$49*(1-Targets!$D$49),"TOO WEAK","OK"))
A22: Camp | B22: Bigger Food Stock | C22: 0 | D22: 0 | E22: =C22-D22 | F22: 35 | G22: 1.5 | H22: 30 | I22: foodCap +25, foodRegen +40%/lv | J22: 7500 | K22: =IF(H22<=0,0,J22/H22) | L22: =IF(K22>Targets!$B$49*(1+Targets!$C$49),"TOO STRONG",IF(K22<Targets!$B$49*(1-Targets!$D$49),"TOO WEAK","OK"))
A23: Other | B23: Auto-Accept | C23: 0 | D23: 0 | E23: =C23-D23 | F23: 150 | G23: 1 | H23: 1 | I23: autoAccept=True | J23: 0 | K23: =IF(H23<=0,0,J23/H23) | L23: =IF(K23>Targets!$B$46*(1+Targets!$C$46),"TOO STRONG",IF(K23<Targets!$B$46*(1-Targets!$D$46),"TOO WEAK","OK"))
A24: Company | B24: Hire Briar | C24: 15 | D24: =Targets!C34 | E24: =C24-D24 | F24: 80 | G24: 1 | H24: 1 | I24: unlockHunter=briar | J24: 30 | K24: =IF(H24<=0,0,J24/H24) | L24: =IF(K24>Targets!$B$48*(1+Targets!$C$48),"TOO STRONG",IF(K24<Targets!$B$48*(1-Targets!$D$48),"TOO WEAK","OK"))
A25: Company | B25: Hire Quill | C25: 90 | D25: =Targets!C37 | E25: =C25-D25 | F25: 200 | G25: 1 | H25: 1 | I25: unlockHunter=quill | J25: 30 | K25: =IF(H25<=0,0,J25/H25) | L25: =IF(K25>Targets!$B$48*(1+Targets!$C$48),"TOO STRONG",IF(K25<Targets!$B$48*(1-Targets!$D$48),"TOO WEAK","OK"))
A26: Company | B26: Hire Moss | C26: 180 | D26: =Targets!C39 | E26: =C26-D26 | F26: 400 | G26: 1 | H26: 1 | I26: unlockHunter=moss | J26: 30 | K26: =IF(H26<=0,0,J26/H26) | L26: =IF(K26>Targets!$B$48*(1+Targets!$C$48),"TOO STRONG",IF(K26<Targets!$B$48*(1-Targets!$D$48),"TOO WEAK","OK"))
A27: Company | B27: Hire Ember | C27: 300 | D27: =Targets!C41 | E27: =C27-D27 | F27: 1200 | G27: 1 | H27: 1 | I27: unlockHunter=ember | J27: 30 | K27: =IF(H27<=0,0,J27/H27) | L27: =IF(K27>Targets!$B$48*(1+Targets!$C$48),"TOO STRONG",IF(K27<Targets!$B$48*(1-Targets!$D$48),"TOO WEAK","OK"))
A28: Company | B28: Hunter Power | C28: 20 | D28: 20 | E28: =C28-D28 | F28: 100 | G28: 1.65 | H28: 20 | I28: hunterPower +30%/lv | J28: 300 | K28: =IF(H28<=0,0,J28/H28) | L28: =IF(K28>Targets!$B$48*(1+Targets!$C$48),"TOO STRONG",IF(K28<Targets!$B$48*(1-Targets!$D$48),"TOO WEAK","OK"))
A29: Company | B29: Bigger Hits | C29: 22 | D29: 22 | E29: =C29-D29 | F29: 140 | G29: 1.7 | H29: 15 | I29: hunterDmg +40%/lv | J29: 270 | K29: =IF(H29<=0,0,J29/H29) | L29: =IF(K29>Targets!$B$48*(1+Targets!$C$48),"TOO STRONG",IF(K29<Targets!$B$48*(1-Targets!$D$48),"TOO WEAK","OK"))
A30: Company | B30: Faster Attacks | C30: 24 | D30: 24 | E30: =C30-D30 | F30: 160 | G30: 1.75 | H30: 12 | I30: hunterAtkSpeed +30%/lv | J30: 162 | K30: =IF(H30<=0,0,J30/H30) | L30: =IF(K30>Targets!$B$48*(1+Targets!$C$48),"TOO STRONG",IF(K30<Targets!$B$48*(1-Targets!$D$48),"TOO WEAK","OK"))
A31: Company | B31: Swift Walk | C31: 18 | D31: 18 | E31: =C31-D31 | F31: 120 | G31: 1 | H31: 1 | I31: hunterMoveSpeed +55%/lv | J31: 13.8 | K31: =IF(H31<=0,0,J31/H31) | L31: =IF(K31>Targets!$B$48*(1+Targets!$C$48),"TOO STRONG",IF(K31<Targets!$B$48*(1-Targets!$D$48),"TOO WEAK","OK"))
A32: Company | B32: Faster Chase | C32: 25 | D32: 25 | E32: =C32-D32 | F32: 220 | G32: 1 | H32: 1 | I32: hunterMoveSpeed +70%/lv | J32: 17.5 | K32: =IF(H32<=0,0,J32/H32) | L32: =IF(K32>Targets!$B$48*(1+Targets!$C$48),"TOO STRONG",IF(K32<Targets!$B$48*(1-Targets!$D$48),"TOO WEAK","OK"))
A33: Company | B33: Hard Charge | C33: 35 | D33: 35 | E33: =C33-D33 | F33: 400 | G33: 1 | H33: 1 | I33: hunterMoveSpeed +90%/lv | J33: 22.5 | K33: =IF(H33<=0,0,J33/H33) | L33: =IF(K33>Targets!$B$48*(1+Targets!$C$48),"TOO STRONG",IF(K33<Targets!$B$48*(1-Targets!$D$48),"TOO WEAK","OK"))
A34: Camp | B34: Loot Luck | C34: 0 | D34: 0 | E34: =C34-D34 | F34: 70 | G34: 1.65 | H34: 20 | I34: lootLuck +10%/lv | J34: 40 | K34: =IF(H34<=0,0,J34/H34) | L34: =IF(K34>Targets!$B$49*(1+Targets!$C$49),"TOO STRONG",IF(K34<Targets!$B$49*(1-Targets!$D$49),"TOO WEAK","OK"))
A35: Other | B35: Area Boss Focus | C35: 0 | D35: 0 | E35: =C35-D35 | F35: 100 | G35: 1.75 | H35: 15 | I35: preyChip +15%/lv | J35: 0 | K35: =IF(H35<=0,0,J35/H35) | L35: =IF(K35>Targets!$B$46*(1+Targets!$C$46),"TOO STRONG",IF(K35<Targets!$B$46*(1-Targets!$D$46),"TOO WEAK","OK"))
A37: Company tip: Hunter Power (+30%/lv) × Bigger Hits (+40%/lv) multiplies — if both flag TOO STRONG, cut one. Pierce should not flag TOO LATE vs Mages unlock (see Journey).

Sheet Monsters
A1: MONSTERS — earnings & fight length (relative balance)
A2: Uses Targets DPS + base HP. Gold/hr and Rank XP/hr should stair-step up by area — if a weaker monster beats a stronger one, fix yellow numbers.
A4: Monster | B4: Area | C4: HP mult | D4: Eff HP | E4: TTK sec | F4: Kills/min | G4: Avg gold | H4: Quota | I4: Finish | J4: Gold/hr | K4: Rank XP/hr | L4: Min/task | M4: vs area median gold/hr | N4: Feel / note
A5: Crawling Hands | B5: Undercroft | C5: 1.4 | D5: =C5*Targets!$B$55 | E5: =IF(Targets!$B$54<=0,0,D5/Targets!$B$54) | F5: =IF(E5<=0,0,60/E5) | G5: 1.5 | H5: 25 | I5: 15 | J5: =F5*60*G5 | K5: =IF(H5<=0,0,(F5*60/H5)*FLOOR(H5*0.5+I5*0.3,1)) | L5: =IF(F5<=0,0,H5/F5) | M5: =IF(J5=0,"",J5/AVERAGEIF($B$5:$B$14,B5,$J$5:$J$14)) | N5: Tanky scrap-crawlers that lumber in slow and soak bolts.
A6: Banshees | B6: Undercroft | C6: 0.7 | D6: =C6*Targets!$B$55 | E6: =IF(Targets!$B$54<=0,0,D6/Targets!$B$54) | F6: =IF(E6<=0,0,60/E6) | G6: 3 | H6: 60 | I6: 35 | J6: =F6*60*G6 | K6: =IF(H6<=0,0,(F6*60/H6)*FLOOR(H6*0.5+I6*0.3,1)) | L6: =IF(F6<=0,0,H6/F6) | M6: =IF(J6=0,"",J6/AVERAGEIF($B$5:$B$14,B6,$J$5:$J$14)) | N6: Frail shriekers that dart fast and slip past lazy aim.
A7: Infernal Mages | B7: Undercroft | C7: 1 | D7: =C7*Targets!$B$55 | E7: =IF(Targets!$B$54<=0,0,D7/Targets!$B$54) | F7: =IF(E7<=0,0,60/E7) | G7: 6.5 | H7: 100 | I7: 60 | J7: =F7*60*G7 | K7: =IF(H7<=0,0,(F7*60/H7)*FLOOR(H7*0.5+I7*0.3,1)) | L7: =IF(F7<=0,0,H7/F7) | M7: =IF(J7=0,"",J7/AVERAGEIF($B$5:$B$14,B7,$J$5:$J$14)) | N7: Clumped casters with a shield until Pierce; gold and ember loot.
A8: Dust Devils | B8: Fenwatch | C8: 1 | D8: =C8*Targets!$B$55 | E8: =IF(Targets!$B$54<=0,0,D8/Targets!$B$54) | F8: =IF(E8<=0,0,60/E8) | G8: 7 | H8: 80 | I8: 80 | J8: =F8*60*G8 | K8: =IF(H8<=0,0,(F8*60/H8)*FLOOR(H8*0.5+I8*0.3,1)) | L8: =IF(F8<=0,0,H8/F8) | M8: =IF(J8=0,"",J8/AVERAGEIF($B$5:$B$14,B8,$J$5:$J$14)) | N8: Spinning grit whirlwinds that chip away at careless hunters.
A9: Gargoyles | B9: Fenwatch | C9: 1 | D9: =C9*Targets!$B$55 | E9: =IF(Targets!$B$54<=0,0,D9/Targets!$B$54) | F9: =IF(E9<=0,0,60/E9) | G9: 10 | H9: 120 | I9: 120 | J9: =F9*60*G9 | K9: =IF(H9<=0,0,(F9*60/H9)*FLOOR(H9*0.5+I9*0.3,1)) | L9: =IF(F9<=0,0,H9/F9) | M9: =IF(J9=0,"",J9/AVERAGEIF($B$5:$B$14,B9,$J$5:$J$14)) | N9: Stone-skinned perchers that shrug off light bolts.
A10: Aberrant Spectres | B10: Fenwatch | C10: 1 | D10: =C10*Targets!$B$55 | E10: =IF(Targets!$B$54<=0,0,D10/Targets!$B$54) | F10: =IF(E10<=0,0,60/E10) | G10: 13 | H10: 150 | I10: 160 | J10: =F10*60*G10 | K10: =IF(H10<=0,0,(F10*60/H10)*FLOOR(H10*0.5+I10*0.3,1)) | L10: =IF(F10<=0,0,H10/F10) | M10: =IF(J10=0,"",J10/AVERAGEIF($B$5:$B$14,B10,$J$5:$J$14)) | N10: Violet ghosts that warp sideways when you line up a shot.
A11: Kurasks | B11: Bonevault | C11: 1 | D11: =C11*Targets!$B$55 | E11: =IF(Targets!$B$54<=0,0,D11/Targets!$B$54) | F11: =IF(E11<=0,0,60/E11) | G11: 16 | H11: 140 | I11: 200 | J11: =F11*60*G11 | K11: =IF(H11<=0,0,(F11*60/H11)*FLOOR(H11*0.5+I11*0.3,1)) | L11: =IF(F11<=0,0,H11/F11) | M11: =IF(J11=0,"",J11/AVERAGEIF($B$5:$B$14,B11,$J$5:$J$14)) | N11: Heavy crypt beasts with thick hides and mean horns.
A12: Gargantuan Boneguards | B12: Bonevault | C12: 1 | D12: =C12*Targets!$B$55 | E12: =IF(Targets!$B$54<=0,0,D12/Targets!$B$54) | F12: =IF(E12<=0,0,60/E12) | G12: 21 | H12: 200 | I12: 280 | J12: =F12*60*G12 | K12: =IF(H12<=0,0,(F12*60/H12)*FLOOR(H12*0.5+I12*0.3,1)) | L12: =IF(F12<=0,0,H12/F12) | M12: =IF(J12=0,"",J12/AVERAGEIF($B$5:$B$14,B12,$J$5:$J$14)) | N12: Towering bone sentries that rattle the vault floors.
A13: Nechryarch Kin | B13: Ash Warrens | C13: 1 | D13: =C13*Targets!$B$55 | E13: =IF(Targets!$B$54<=0,0,D13/Targets!$B$54) | F13: =IF(E13<=0,0,60/E13) | G13: 27 | H13: 180 | I13: 350 | J13: =F13*60*G13 | K13: =IF(H13<=0,0,(F13*60/H13)*FLOOR(H13*0.5+I13*0.3,1)) | L13: =IF(F13<=0,0,H13/F13) | M13: =IF(J13=0,"",J13/AVERAGEIF($B$5:$B$14,B13,$J$5:$J$14)) | N13: Ash-born kin that swarm in packs from the warrens.
A14: Abyssal Demons | B14: Ash Warrens | C14: 1 | D14: =C14*Targets!$B$55 | E14: =IF(Targets!$B$54<=0,0,D14/Targets!$B$54) | F14: =IF(E14<=0,0,60/E14) | G14: 33.5 | H14: 250 | I14: 450 | J14: =F14*60*G14 | K14: =IF(H14<=0,0,(F14*60/H14)*FLOOR(H14*0.5+I14*0.3,1)) | L14: =IF(F14<=0,0,H14/F14) | M14: =IF(J14=0,"",J14/AVERAGEIF($B$5:$B$14,B14,$J$5:$J$14)) | N14: Deep-abyss brutes that burn through Food and patience.
A16: Col M ≈ 1.0 means on-par with other monsters in that area for gold/hr. >>1 = printer; <<1 = poor.

Sheet Mastery
A1: MASTERY — perks at 3 / 6 / 10 (specialty without breaking the game)
A2: Each monster’s mastery should reinforce its fantasy (Hands=scraps, Banshees=points/offline, Mages=food/bolts). Flag uses Mastery perk budget on Targets.
A4: Monster | B4: At | C4: Perk text | D4: scrap+ | E4: points+ | F4: offline min | G4: foodEff+ | H4: killMult+ | I4: Power score | J4: Flag
A5: Crawling Hands | B5: 3 | C5: +5% global scrap chance | D5: 0.05 | I5: 4 | J5: =IF(I5>Targets!$B$50*(1+Targets!$C$50),"TOO STRONG",IF(I5<Targets!$B$50*(1-Targets!$D$50),"TOO WEAK","OK"))
A6: Crawling Hands | B6: 6 | C6: +8% global scrap chance | D6: 0.08 | I6: 6.4 | J6: =IF(I6>Targets!$B$50*(1+Targets!$C$50),"TOO STRONG",IF(I6<Targets!$B$50*(1-Targets!$D$50),"TOO WEAK","OK"))
A7: Crawling Hands | B7: 10 | C7: +12% global scrap chance | D7: 0.12 | I7: 9.6 | J7: =IF(I7>Targets!$B$50*(1+Targets!$C$50),"TOO STRONG",IF(I7<Targets!$B$50*(1-Targets!$D$50),"TOO WEAK","OK"))
A8: Banshees | B8: 3 | C8: +4% contract points | E8: 0.04 | I8: 4 | J8: =IF(I8>Targets!$B$50*(1+Targets!$C$50),"TOO STRONG",IF(I8<Targets!$B$50*(1-Targets!$D$50),"TOO WEAK","OK"))
A9: Banshees | B9: 6 | C9: +15 min offline cap | F9: 15 | I9: 6 | J9: =IF(I9>Targets!$B$50*(1+Targets!$C$50),"TOO STRONG",IF(I9<Targets!$B$50*(1-Targets!$D$50),"TOO WEAK","OK"))
A10: Banshees | B10: 10 | C10: +8% points · +20 min offline cap | E10: 0.08 | F10: 20 | I10: 16 | J10: =IF(I10>Targets!$B$50*(1+Targets!$C$50),"TOO STRONG",IF(I10<Targets!$B$50*(1-Targets!$D$50),"TOO WEAK","OK"))
A11: Infernal Mages | B11: 3 | C11: +5% food efficiency | G11: 0.05 | I11: 3 | J11: =IF(I11>Targets!$B$50*(1+Targets!$C$50),"TOO STRONG",IF(I11<Targets!$B$50*(1-Targets!$D$50),"TOO WEAK","OK"))
A12: Infernal Mages | B12: 6 | C12: +4% bolt focus feel | H12: 0.04 | I12: 4 | J12: =IF(I12>Targets!$B$50*(1+Targets!$C$50),"TOO STRONG",IF(I12<Targets!$B$50*(1-Targets!$D$50),"TOO WEAK","OK"))
A13: Infernal Mages | B13: 10 | C13: +8% food efficiency · +6% bolt focus | G13: 0.08 | H13: 0.06 | I13: 10.8 | J13: =IF(I13>Targets!$B$50*(1+Targets!$C$50),"TOO STRONG",IF(I13<Targets!$B$50*(1-Targets!$D$50),"TOO WEAK","OK"))
A15: Monsters without mastery rows (later areas) still need an identity pass — blank is a TODO, not “balanced.”
