Workbook

Sheet Start Here
A1: AFK Slayer — Play Sheet
A2: A spreadsheet you can play like the game. Yellow cells are inputs; blue cells recalculate. Built from the live game code (not design docs).
A4: What the game is
A5: AFK Slayer is an idle hunt game. You take a Task (a kill quota) on a monster, fire bolts while you play, and hire hunters who keep fighting when you step away. Kills earn gold, Slayer points, scraps, and signature mats. Slayer points fill a boss meter. When it is full you Fight the Level boss. Win and the next Level unlocks.
A7: The loop (7 steps)
A8: 1. Take a Task on a Level 1 hunt monster (start with Bristle Cub).
A9: 2. Hunt — hold to fire bolts. Kills give gold + Slayer points + sometimes scraps/mats.
A10: 3. Spend gold (and later Slayer points / scraps / mats) on Progress upgrades: Combat, Gear, Company, Camp.
A11: 4. Hire Briar when you can — hunters add their own damage, separate from your bolts.
A12: 5. Fill the Level boss meter with Slayer points (Level 1 needs 120).
A13: 6. Tap Fight boss. Beat Elder Thornpelt to unlock Level 2 (then Ashfang Alpha → Level 3 → Nightweave).
A14: 7. Go AFK when you leave — offline progress runs on the AFK kill rate up to your away cap, and stops if food runs out.
A16: Currencies
A17: Currency | B17: What it does
A18: Gold | B18: Buy most upgrades, gear, and Briar/Quill. Earned every kill.
A19: Slayer points | B19: Fill the boss meter; also buy some late upgrades (Mithril+, Moss/Ember).
A20: Scraps | B20: Camp Scrapwork side path. Chance drop on kills.
A21: Signature mats | B21: Per-family drops (Pelt Scrap, Dire Claw, …). Spend at the Forge.
A22: Food | B22: Hunters eat food while AFK. Empty food stops offline kills. Buy more for 10 gold → +40 food.
A24: Active play vs AFK
A25: Active Hunt: you hold to fire. Kill rate gets the active hold bonus (×1.4). Boss fights only happen while you play.
A26: Go AFK: uses the idle kill-rate formula with NO active bonus. Progress only counts up to your away cap (starts at 6 hours = 360 minutes; Camp Offline Cap, Scrapwork Wick Wire, and Forge Fang Charm add more).
A27: Anything beyond the away cap is lost. Food regenerates during the counted window, then kills spend food — if food runs out, hunting stops even if cap time remains.
A28: In the Play tab, set Action = Go AFK and put hours in the Min or Hrs column. The sheet shows how many hours actually counted.
A30: How to use the Play tab
A31: Each row is one step. Yellow cells are your inputs: Action, Target, Min or Hrs (minutes for Hunt, hours for Go AFK).
A32: Pick Action from the dropdown, Target from the list (monster / upgrade / hunter / boss name).
A33: Blue cells are the running game state after that step: gold, meter, scraps, mats, food, DPS, kills, boss result.
A34: Green Status = OK (applied). Red Status = Can’t — the step did not spend or earn (read the Message).
A35: About 20 example rows are prefilled to a first Elder Thornpelt fight (including one 8-hour AFK). Keep playing in the empty rows below.
A36: Edit Aim uptime and Boss patience on the Rules & Formulas tab if you want different fight fairness assumptions.

Sheet Play
A1: PLAY — each row is a step. Yellow=inputs. Blue=calculated. Prefill=new-player path to Elder (includes Go AFK 8h). Min or Hrs = minutes for Hunt, hours for Go AFK.
A2: Step | B2: Action | C2: Target | D2: Min or Hrs | E2: Status | F2: Message | G2: Level | H2: Gold | I2: Meter Sp | J2: Scraps | K2: Pelt | L2: DireClaw | M2: Food | N2: IdlePower | O2: HunterLabor | P2: Rate Active | Q2: Rate AFK | R2: Kills | S2: PlayerDPS | T2: HunterDPS | U2: TotalDPS | V2: Boss ready? | W2: Boss TTK s | X2: Boss result | Y2: AFK counted h | Z2: OffCap min | AA2: OwnIdle | AB2: OwnIron | AC2: OwnSteel | AD2: OwnBriar | AE2: OwnHuntPwr | AF2: OwnBigger | AG2: OwnSwift | AH2: OwnLoot | AI2: OwnOffCap | AJ2: OwnFoodStock | AK2: OwnFoodEff
A3: 1 | B3: Hunt | C3: Bristle Cub | D3: 28 | E3: =IF(B3="","",IF(OR(B3="Hunt",B3="Go AFK"),IF(C3="","Can't","OK"),IF(B3="Fight boss",IF(0<IF((IFERROR(VLOOKUP(C3,Monsters!$T$4:$AH$15,15,FALSE),0))=0,120,IFERROR(VLOOKUP(C3,Monsters!$T$4:$AH$15,15,FALSE),0)),"Can't","OK"),IF(B3="Hire hunter",IF(AND(C3="Briar",0>=1),"Can't",IF('Rules & Formulas'!B16<IF(C3="Briar",140,IF(C3="Quill",3650,IF(C3="Moss",4850,IF(C3="Ember",12200,0)))),"Can't","OK")),IF(OR(B3="Buy upgrade",B3="Forge/Scrapwork buy"),IF(IFERROR(VLOOKUP(C3,Upgrades!$N$4:$T$47,2,FALSE),0)="points","Can't",IF(IFERROR(VLOOKUP(C3,Upgrades!$N$4:$T$47,2,FALSE),0)="gold",IF('Rules & Formulas'!B16<IFERROR(FLOOR(IFERROR(VLOOKUP(C3,Upgrades!$N$4:$T$47,3,FALSE),0)*(IFERROR(VLOOKUP(C3,Upgrades!$N$4:$T$47,4,FALSE),0)^(0)),1),0),"Can't","OK"),IF(IFERROR(VLOOKUP(C3,Upgrades!$N$4:$T$47,2,FALSE),0)="scraps",IF(0<IFERROR(FLOOR(IFERROR(VLOOKUP(C3,Upgrades!$N$4:$T$47,3,FALSE),0)*(IFERROR(VLOOKUP(C3,Upgrades!$N$4:$T$47,4,FALSE),0)^(0)),1),0),"Can't","OK"),IF(IFERROR(VLOOKUP(C3,Upgrades!$N$4:$T$47,2,FALSE),0)="mats","Can't","OK")))),"Check"))))) | F3: =IF(B3="","",IF(AND(B3="Fight boss",0<IF((IFERROR(VLOOKUP(C3,Monsters!$T$4:$AH$15,15,FALSE),0))=0,120,IFERROR(VLOOKUP(C3,Monsters!$T$4:$AH$15,15,FALSE),0))),"Can't — need "&TEXT(IF((IFERROR(VLOOKUP(C3,Monsters!$T$4:$AH$15,15,FALSE),0))=0,120,IFERROR(VLOOKUP(C3,Monsters!$T$4:$AH$15,15,FALSE),0))-0,"0.0")&" more Slayer points on the meter",IF(AND(B3="Hire hunter",C3="Briar",0>=1),"Can't — already hired",IF(AND(B3="Hire hunter",'Rules & Formulas'!B16<IF(C3="Briar",140,IF(C3="Quill",3650,IF(C3="Moss",4850,IF(C3="Ember",12200,0))))),"Can't — need "&TEXT(IF(C3="Briar",140,IF(C3="Quill",3650,IF(C3="Moss",4850,IF(C3="Ember",12200,0))))-'Rules & Formulas'!B16,"0")&" more gold",IF(AND(OR(B3="Buy upgrade",B3="Forge/Scrapwork buy"),IFERROR(VLOOKUP(C3,Upgrades!$N$4:$T$47,2,FALSE),0)="points"),"Can't — Sp-wallet spends not tracked here",IF(AND(OR(B3="Buy upgrade",B3="Forge/Scrapwork buy"),IFERROR(VLOOKUP(C3,Upgrades!$N$4:$T$47,2,FALSE),0)="gold",'Rules & Formulas'!B16<IFERROR(FLOOR(IFERROR(VLOOKUP(C3,Upgrades!$N$4:$T$47,3,FALSE),0)*(IFERROR(VLOOKUP(C3,Upgrades!$N$4:$T$47,4,FALSE),0)^(0)),1),0)),"Can't — need "&TEXT(IFERROR(FLOOR(IFERROR(VLOOKUP(C3,Upgrades!$N$4:$T$47,3,FALSE),0)*(IFERROR(VLOOKUP(C3,Upgrades!$N$4:$T$47,4,FALSE),0)^(0)),1),0)-'Rules & Formulas'!B16,"0")&" more gold",IF(AND(OR(B3="Buy upgrade",B3="Forge/Scrapwork buy"),IFERROR(VLOOKUP(C3,Upgrades!$N$4:$T$47,2,FALSE),0)="scraps",0<IFERROR(FLOOR(IFERROR(VLOOKUP(C3,Upgrades!$N$4:$T$47,3,FALSE),0)*(IFERROR(VLOOKUP(C3,Upgrades!$N$4:$T$47,4,FALSE),0)^(0)),1),0)),"Can't — need "&TEXT(IFERROR(FLOOR(IFERROR(VLOOKUP(C3,Upgrades!$N$4:$T$47,3,FALSE),0)*(IFERROR(VLOOKUP(C3,Upgrades!$N$4:$T$47,4,FALSE),0)^(0)),1),0)-0,"0")&" more scraps",IF(AND(B3="Fight boss",E3="OK",(IF((((105/'Rules & Formulas'!B10)*'Rules & Formulas'!B11+IF(0>=1,(MAX(1,ROUND('Rules & Formulas'!B18*(1+0.3*0)*(1+0.4*0),0)))*(1000/'Rules & Formulas'!B19)*MIN(0.95,'Rules & Formulas'!B20*SQRT(1+0.55*(0>=1))),0)))<=0,9999,(IFERROR(VLOOKUP(C3,Monsters!$T$4:$AH$15,2,FALSE),0))/(((105/'Rules & Formulas'!B10)*'Rules & Formulas'!B11+IF(0>=1,(MAX(1,ROUND('Rules & Formulas'!B18*(1+0.3*0)*(1+0.4*0),0)))*(1000/'Rules & Formulas'!B19)*MIN(0.95,'Rules & Formulas'!B20*SQRT(1+0.55*(0>=1))),0))))<='Rules & Formulas'!B12)),"WIN — boss down, next Level unlocks",IF(AND(B3="Fight boss",E3="OK"),"LOSE — TTK "&TEXT(IF((((105/'Rules & Formulas'!B10)*'Rules & Formulas'!B11+IF(0>=1,(MAX(1,ROUND('Rules & Formulas'!B18*(1+0.3*0)*(1+0.4*0),0)))*(1000/'Rules & Formulas'!B19)*MIN(0.95,'Rules & Formulas'!B20*SQRT(1+0.55*(0>=1))),0)))<=0,9999,(IFERROR(VLOOKUP(C3,Monsters!$T$4:$AH$15,2,FALSE),0))/(((105/'Rules & Formulas'!B10)*'Rules & Formulas'!B11+IF(0>=1,(MAX(1,ROUND('Rules & Formulas'!B18*(1+0.3*0)*(1+0.4*0),0)))*(1000/'Rules & Formulas'!B19)*MIN(0.95,'Rules & Formulas'!B20*SQRT(1+0.55*(0>=1))),0)))),"0")&"s > patience "&TEXT('Rules & Formulas'!B12,"0")&"s (leave resets HP)",IF(B3="Go AFK","AFK resolved (see AFK counted h)","Applied"))))))))) | G3: =IF(AND((E3="OK"),B3="Fight boss",(IF((((105/'Rules & Formulas'!B10)*'Rules & Formulas'!B11+IF(0>=1,(MAX(1,ROUND('Rules & Formulas'!B18*(1+0.3*0)*(1+0.4*0),0)))*(1000/'Rules & Formulas'!B19)*MIN(0.95,'Rules & Formulas'!B20*SQRT(1+0.55*(0>=1))),0)))<=0,9999,(IFERROR(VLOOKUP(C3,Monsters!$T$4:$AH$15,2,FALSE),0))/(((105/'Rules & Formulas'!B10)*'Rules & Formulas'!B11+IF(0>=1,(MAX(1,ROUND('Rules & Formulas'!B18*(1+0.3*0)*(1+0.4*0),0)))*(1000/'Rules & Formulas'!B19)*MIN(0.95,'Rules & Formulas'!B20*SQRT(1+0.55*(0>=1))),0))))<='Rules & Formulas'!B12),C3="Elder Thornpelt"),2,IF(AND((E3="OK"),B3="Fight boss",(IF((((105/'Rules & Formulas'!B10)*'Rules & Formulas'!B11+IF(0>=1,(MAX(1,ROUND('Rules & Formulas'!B18*(1+0.3*0)*(1+0.4*0),0)))*(1000/'Rules & Formulas'!B19)*MIN(0.95,'Rules & Formulas'!B20*SQRT(1+0.55*(0>=1))),0)))<=0,9999,(IFERROR(VLOOKUP(C3,Monsters!$T$4:$AH$15,2,FALSE),0))/(((105/'Rules & Formulas'!B10)*'Rules & Formulas'!B11+IF(0>=1,(MAX(1,ROUND('Rules & Formulas'!B18*(1+0.3*0)*(1+0.4*0),0)))*(1000/'Rules & Formulas'!B19)*MIN(0.95,'Rules & Formulas'!B20*SQRT(1+0.55*(0>=1))),0))))<='Rules & Formulas'!B12),C3="Ashfang Alpha"),3,1)) | H3: =MAX(0,'Rules & Formulas'!B16+IF(AND((E3="OK"),B3="Hunt"),(IF(B3="Hunt",(('Rules & Formulas'!B4*(1+0.08)*('Rules & Formulas'!B5+0)*IFERROR(VLOOKUP(C3,Monsters!$T$4:$AH$15,10,FALSE),0)*IFERROR(VLOOKUP(C3,Monsters!$T$4:$AH$15,9,FALSE),0))*'Rules & Formulas'!B6)*IF(D3="",0,D3),0))*(IFERROR(VLOOKUP(C3,Monsters!$T$4:$AH$15,3,FALSE),0))*1+(IF(OR(B3<>"Hunt",IFERROR(VLOOKUP(C3,Monsters!$T$4:$AH$15,6,FALSE),0)=0),0,FLOOR((IF(B3="Hunt",(('Rules & Formulas'!B4*(1+0.08)*('Rules & Formulas'!B5+0)*IFERROR(VLOOKUP(C3,Monsters!$T$4:$AH$15,10,FALSE),0)*IFERROR(VLOOKUP(C3,Monsters!$T$4:$AH$15,9,FALSE),0))*'Rules & Formulas'!B6)*IF(D3="",0,D3),0))/MAX(1,IFERROR(VLOOKUP(C3,Monsters!$T$4:$AH$15,6,FALSE),0)),1)))*(IFERROR(VLOOKUP(C3,Monsters!$T$4:$AH$15,7,FALSE),0))*0.5*1,0)+IF(AND((E3="OK"),B3="Go AFK"),(IF(B3="Go AFK",MIN(IF((IF((IFERROR(VLOOKUP(C3,Monsters!$T$4:$AH$15,8,FALSE),0))=0,0.35,IFERROR(VLOOKUP(C3,Monsters!$T$4:$AH$15,8,FALSE),0))/1)<=0,999999,FLOOR(MIN('Rules & Formulas'!B15,'Rules & Formulas'!B17+'Rules & Formulas'!B14*(MIN(IF(B3="Go AFK",IF(D3="",0,D3),0),'Rules & Formulas'!B13/60)*60))/(IF((IFERROR(VLOOKUP(C3,Monsters!$T$4:$AH$15,8,FALSE),0))=0,0.35,IFERROR(VLOOKUP(C3,Monsters!$T$4:$AH$15,8,FALSE),0))/1),1)),('Rules & Formulas'!B4*(1+0.08)*('Rules & Formulas'!B5+0)*IFERROR(VLOOKUP(C3,Monsters!$T$4:$AH$15,10,FALSE),0)*IFERROR(VLOOKUP(C3,Monsters!$T$4:$AH$15,9,FALSE),0))*(MIN(IF(B3="Go AFK",IF(D3="",0,D3),0),'Rules & Formulas'!B13/60)*60)),0))*(IFERROR(VLOOKUP(C3,Monsters!$T$4:$AH$15,3,FALSE),0))*1+(IF(OR(B3<>"Go AFK",IFERROR(VLOOKUP(C3,Monsters!$T$4:$AH$15,6,FALSE),0)=0),0,FLOOR((IF(B3="Go AFK",MIN(IF((IF((IFERROR(VLOOKUP(C3,Monsters!$T$4:$AH$15,8,FALSE),0))=0,0.35,IFERROR(VLOOKUP(C3,Monsters!$T$4:$AH$15,8,FALSE),0))/1)<=0,999999,FLOOR(MIN('Rules & Formulas'!B15,'Rules & Formulas'!B17+'Rules & Formulas'!B14*(MIN(IF(B3="Go AFK",IF(D3="",0,D3),0),'Rules & Formulas'!B13/60)*60))/(IF((IFERROR(VLOOKUP(C3,Monsters!$T$4:$AH$15,8,FALSE),0))=0,0.35,IFERROR(VLOOKUP(C3,Monsters!$T$4:$AH$15,8,FALSE),0))/1),1)),('Rules & Formulas'!B4*(1+0.08)*('Rules & Formulas'!B5+0)*IFERROR(VLOOKUP(C3,Monsters!$T$4:$AH$15,10,FALSE),0)*IFERROR(VLOOKUP(C3,Monsters!$T$4:$AH$15,9,FALSE),0))*(MIN(IF(B3="Go AFK",IF(D3="",0,D3),0),'Rules & Formulas'!B13/60)*60)),0))/MAX(1,IFERROR(VLOOKUP(C3,Monsters!$T$4:$AH$15,6,FALSE),0)),1)))*(IFERROR(VLOOKUP(C3,Monsters!$T$4:$AH$15,7,FALSE),0))*0.5*1,0)+IF(AND((E3="OK"),B3="Fight boss",(IF((((105/'Rules & Formulas'!B10)*'Rules & Formulas'!B11+IF(0>=1,(MAX(1,ROUND('Rules & Formulas'!B18*(1+0.3*0)*(1+0.4*0),0)))*(1000/'Rules & Formulas'!B19)*MIN(0.95,'Rules & Formulas'!B20*SQRT(1+0.55*(0>=1))),0)))<=0,9999,(IFERROR(VLOOKUP(C3,Monsters!$T$4:$AH$15,2,FALSE),0))/(((105/'Rules & Formulas'!B10)*'Rules & Formulas'!B11+IF(0>=1,(MAX(1,ROUND('Rules & Formulas'!B18*(1+0.3*0)*(1+0.4*0),0)))*(1000/'Rules & Formulas'!B19)*MIN(0.95,'Rules & Formulas'!B20*SQRT(1+0.55*(0>=1))),0))))<='Rules & Formulas'!B12)),IFERROR(VLOOKUP(C3,Monsters!$T$4:$AH$15,3,FALSE),0),0)-IF(AND((E3="OK"),OR(B3="Buy upgrade",B3="Forge/Scrapwork buy"),IFERROR(VLOOKUP(C3,Upgrades!$N$4:$T$47,2,FALSE),0)="gold"),IFERROR(FLOOR(IFERROR(VLOOKUP(C3,Upgrades!$N$4:$T$47,3,FALSE),0)*(IFERROR(VLOOKUP(C3,Upgrades!$N$4:$T$47,4,FALSE),0)^(0)),1),0),0)-IF(AND((E3="OK"),B3="Hire hunter"),IF(C3="Briar",140,IF(C3="Quill",3650,IF(C3="Moss",4850,IF(C3="Ember",12200,0)))),0)) | I3: =IF(AND((E3="OK"),B3="Fight boss",(IF((((105/'Rules & Formulas'!B10)*'Rules & Formulas'!B11+IF(0>=1,(MAX(1,ROUND('Rules & Formulas'!B18*(1+0.3*0)*(1+0.4*0),0)))*(1000/'Rules & Formulas'!B19)*MIN(0.95,'Rules & Formulas'!B20*SQRT(1+0.55*(0>=1))),0)))<=0,9999,(IFERROR(VLOOKUP(C3,Monsters!$T$4:$AH$15,2,FALSE),0))/(((105/'Rules & Formulas'!B10)*'Rules & Formulas'!B11+IF(0>=1,(MAX(1,ROUND('Rules & Formulas'!B18*(1+0.3*0)*(1+0.4*0),0)))*(1000/'Rules & Formulas'!B19)*MIN(0.95,'Rules & Formulas'!B20*SQRT(1+0.55*(0>=1))),0))))<='Rules & Formulas'!B12)),0,MIN(IF(1<=1,120,IF(1=2,280,600)),0+IF(AND((E3="OK"),B3="Hunt"),((IF(B3="Hunt",(('Rules & Formulas'!B4*(1+0.08)*('Rules & Formulas'!B5+0)*IFERROR(VLOOKUP(C3,Monsters!$T$4:$AH$15,10,FALSE),0)*IFERROR(VLOOKUP(C3,Monsters!$T$4:$AH$15,9,FALSE),0))*'Rules & Formulas'!B6)*IF(D3="",0,D3),0))*(IFERROR(VLOOKUP(C3,Monsters!$T$4:$AH$15,4,FALSE),0))+(IF(OR(B3<>"Hunt",IFERROR(VLOOKUP(C3,Monsters!$T$4:$AH$15,6,FALSE),0)=0),0,FLOOR((IF(B3="Hunt",(('Rules & Formulas'!B4*(1+0.08)*('Rules & Formulas'!B5+0)*IFERROR(VLOOKUP(C3,Monsters!$T$4:$AH$15,10,FALSE),0)*IFERROR(VLOOKUP(C3,Monsters!$T$4:$AH$15,9,FALSE),0))*'Rules & Formulas'!B6)*IF(D3="",0,D3),0))/MAX(1,IFERROR(VLOOKUP(C3,Monsters!$T$4:$AH$15,6,FALSE),0)),1)))*(IFERROR(VLOOKUP(C3,Monsters!$T$4:$AH$15,7,FALSE),0))),0)+IF(AND((E3="OK"),B3="Go AFK"),((IF(B3="Go AFK",MIN(IF((IF((IFERROR(VLOOKUP(C3,Monsters!$T$4:$AH$15,8,FALSE),0))=0,0.35,IFERROR(VLOOKUP(C3,Monsters!$T$4:$AH$15,8,FALSE),0))/1)<=0,999999,FLOOR(MIN('Rules & Formulas'!B15,'Rules & Formulas'!B17+'Rules & Formulas'!B14*(MIN(IF(B3="Go AFK",IF(D3="",0,D3),0),'Rules & Formulas'!B13/60)*60))/(IF((IFERROR(VLOOKUP(C3,Monsters!$T$4:$AH$15,8,FALSE),0))=0,0.35,IFERROR(VLOOKUP(C3,Monsters!$T$4:$AH$15,8,FALSE),0))/1),1)),('Rules & Formulas'!B4*(1+0.08)*('Rules & Formulas'!B5+0)*IFERROR(VLOOKUP(C3,Monsters!$T$4:$AH$15,10,FALSE),0)*IFERROR(VLOOKUP(C3,Monsters!$T$4:$AH$15,9,FALSE),0))*(MIN(IF(B3="Go AFK",IF(D3="",0,D3),0),'Rules & Formulas'!B13/60)*60)),0))*(IFERROR(VLOOKUP(C3,Monsters!$T$4:$AH$15,4,FALSE),0))+(IF(OR(B3<>"Go AFK",IFERROR(VLOOKUP(C3,Monsters!$T$4:$AH$15,6,FALSE),0)=0),0,FLOOR((IF(B3="Go AFK",MIN(IF((IF((IFERROR(VLOOKUP(C3,Monsters!$T$4:$AH$15,8,FALSE),0))=0,0.35,IFERROR(VLOOKUP(C3,Monsters!$T$4:$AH$15,8,FALSE),0))/1)<=0,999999,FLOOR(MIN('Rules & Formulas'!B15,'Rules & Formulas'!B17+'Rules & Formulas'!B14*(MIN(IF(B3="Go AFK",IF(D3="",0,D3),0),'Rules & Formulas'!B13/60)*60))/(IF((IFERROR(VLOOKUP(C3,Monsters!$T$4:$AH$15,8,FALSE),0))=0,0.35,IFERROR(VLOOKUP(C3,Monsters!$T$4:$AH$15,8,FALSE),0))/1),1)),('Rules & Formulas'!B4*(1+0.08)*('Rules & Formulas'!B5+0)*IFERROR(VLOOKUP(C3,Monsters!$T$4:$AH$15,10,FALSE),0)*IFERROR(VLOOKUP(C3,Monsters!$T$4:$AH$15,9,FALSE),0))*(MIN(IF(B3="Go AFK",IF(D3="",0,D3),0),'Rules & Formulas'!B13/60)*60)),0))/MAX(1,IFERROR(VLOOKUP(C3,Monsters!$T$4:$AH$15,6,FALSE),0)),1)))*(IFERROR(VLOOKUP(C3,Monsters!$T$4:$AH$15,7,FALSE),0))),0))) | J3: =MAX(0,0+IF(AND((E3="OK"),B3="Hunt"),(IF(B3="Hunt",(('Rules & Formulas'!B4*(1+0.08)*('Rules & Formulas'!B5+0)*IFERROR(VLOOKUP(C3,Monsters!$T$4:$AH$15,10,FALSE),0)*IFERROR(VLOOKUP(C3,Monsters!$T$4:$AH$15,9,FALSE),0))*'Rules & Formulas'!B6)*IF(D3="",0,D3),0))*(IFERROR(VLOOKUP(C3,Monsters!$T$4:$AH$15,5,FALSE),0)),0)+IF(AND((E3="OK"),B3="Go AFK"),(IF(B3="Go AFK",MIN(IF((IF((IFERROR(VLOOKUP(C3,Monsters!$T$4:$AH$15,8,FALSE),0))=0,0.35,IFERROR(VLOOKUP(C3,Monsters!$T$4:$AH$15,8,FALSE),0))/1)<=0,999999,FLOOR(MIN('Rules & Formulas'!B15,'Rules & Formulas'!B17+'Rules & Formulas'!B14*(MIN(IF(B3="Go AFK",IF(D3="",0,D3),0),'Rules & Formulas'!B13/60)*60))/(IF((IFERROR(VLOOKUP(C3,Monsters!$T$4:$AH$15,8,FALSE),0))=0,0.35,IFERROR(VLOOKUP(C3,Monsters!$T$4:$AH$15,8,FALSE),0))/1),1)),('Rules & Formulas'!B4*(1+0.08)*('Rules & Formulas'!B5+0)*IFERROR(VLOOKUP(C3,Monsters!$T$4:$AH$15,10,FALSE),0)*IFERROR(VLOOKUP(C3,Monsters!$T$4:$AH$15,9,FALSE),0))*(MIN(IF(B3="Go AFK",IF(D3="",0,D3),0),'Rules & Formulas'!B13/60)*60)),0))*(IFERROR(VLOOKUP(C3,Monsters!$T$4:$AH$15,5,FALSE),0)),0)-IF(AND((E3="OK"),OR(B3="Buy upgrade",B3="Forge/Scrapwork buy"),IFERROR(VLOOKUP(C3,Upgrades!$N$4:$T$47,2,FALSE),0)="scraps"),IFERROR(FLOOR(IFERROR(VLOOKUP(C3,Upgrades!$N$4:$T$47,3,FALSE),0)*(IFERROR(VLOOKUP(C3,Upgrades!$N$4:$T$47,4,FALSE),0)^(0)),1),0),0)) | K3: =MAX(0,0+IF(AND((E3="OK"),B3="Hunt"),IF(C3="Thornpelt Bear",(IF(B3="Hunt",(('Rules & Formulas'!B4*(1+0.08)*('Rules & Formulas'!B5+0)*IFERROR(VLOOKUP(C3,Monsters!$T$4:$AH$15,10,FALSE),0)*IFERROR(VLOOKUP(C3,Monsters!$T$4:$AH$15,9,FALSE),0))*'Rules & Formulas'!B6)*IF(D3="",0,D3),0))*0.12,0),0)+IF(AND((E3="OK"),B3="Go AFK"),IF(C3="Thornpelt Bear",(IF(B3="Go AFK",MIN(IF((IF((IFERROR(VLOOKUP(C3,Monsters!$T$4:$AH$15,8,FALSE),0))=0,0.35,IFERROR(VLOOKUP(C3,Monsters!$T$4:$AH$15,8,FALSE),0))/1)<=0,999999,FLOOR(MIN('Rules & Formulas'!B15,'Rules & Formulas'!B17+'Rules & Formulas'!B14*(MIN(IF(B3="Go AFK",IF(D3="",0,D3),0),'Rules & Formulas'!B13/60)*60))/(IF((IFERROR(VLOOKUP(C3,Monsters!$T$4:$AH$15,8,FALSE),0))=0,0.35,IFERROR(VLOOKUP(C3,Monsters!$T$4:$AH$15,8,FALSE),0))/1),1)),('Rules & Formulas'!B4*(1+0.08)*('Rules & Formulas'!B5+0)*IFERROR(VLOOKUP(C3,Monsters!$T$4:$AH$15,10,FALSE),0)*IFERROR(VLOOKUP(C3,Monsters!$T$4:$AH$15,9,FALSE),0))*(MIN(IF(B3="Go AFK",IF(D3="",0,D3),0),'Rules & Formulas'!B13/60)*60)),0))*0.12,0),0)) | L3: =MAX(0,0+IF(AND((E3="OK"),B3="Hunt"),IF(C3="Dire Thornpelt",(IF(B3="Hunt",(('Rules & Formulas'!B4*(1+0.08)*('Rules & Formulas'!B5+0)*IFERROR(VLOOKUP(C3,Monsters!$T$4:$AH$15,10,FALSE),0)*IFERROR(VLOOKUP(C3,Monsters!$T$4:$AH$15,9,FALSE),0))*'Rules & Formulas'!B6)*IF(D3="",0,D3),0))*0.1,0),0)+IF(AND((E3="OK"),B3="Go AFK"),IF(C3="Dire Thornpelt",(IF(B3="Go AFK",MIN(IF((IF((IFERROR(VLOOKUP(C3,Monsters!$T$4:$AH$15,8,FALSE),0))=0,0.35,IFERROR(VLOOKUP(C3,Monsters!$T$4:$AH$15,8,FALSE),0))/1)<=0,999999,FLOOR(MIN('Rules & Formulas'!B15,'Rules & Formulas'!B17+'Rules & Formulas'!B14*(MIN(IF(B3="Go AFK",IF(D3="",0,D3),0),'Rules & Formulas'!B13/60)*60))/(IF((IFERROR(VLOOKUP(C3,Monsters!$T$4:$AH$15,8,FALSE),0))=0,0.35,IFERROR(VLOOKUP(C3,Monsters!$T$4:$AH$15,8,FALSE),0))/1),1)),('Rules & Formulas'!B4*(1+0.08)*('Rules & Formulas'!B5+0)*IFERROR(VLOOKUP(C3,Monsters!$T$4:$AH$15,10,FALSE),0)*IFERROR(VLOOKUP(C3,Monsters!$T$4:$AH$15,9,FALSE),0))*(MIN(IF(B3="Go AFK",IF(D3="",0,D3),0),'Rules & Formulas'!B13/60)*60)),0))*0.1,0),0)) | M3: =IF(AND((E3="OK"),B3="Go AFK"),MAX(0,MIN('Rules & Formulas'!B15,'Rules & Formulas'!B17+'Rules & Formulas'!B14*(MIN(IF(B3="Go AFK",IF(D3="",0,D3),0),'Rules & Formulas'!B13/60)*60))-(IF(B3="Go AFK",MIN(IF((IF((IFERROR(VLOOKUP(C3,Monsters!$T$4:$AH$15,8,FALSE),0))=0,0.35,IFERROR(VLOOKUP(C3,Monsters!$T$4:$AH$15,8,FALSE),0))/1)<=0,999999,FLOOR(MIN('Rules & Formulas'!B15,'Rules & Formulas'!B17+'Rules & Formulas'!B14*(MIN(IF(B3="Go AFK",IF(D3="",0,D3),0),'Rules & Formulas'!B13/60)*60))/(IF((IFERROR(VLOOKUP(C3,Monsters!$T$4:$AH$15,8,FALSE),0))=0,0.35,IFERROR(VLOOKUP(C3,Monsters!$T$4:$AH$15,8,FALSE),0))/1),1)),('Rules & Formulas'!B4*(1+0.08)*('Rules & Formulas'!B5+0)*IFERROR(VLOOKUP(C3,Monsters!$T$4:$AH$15,10,FALSE),0)*IFERROR(VLOOKUP(C3,Monsters!$T$4:$AH$15,9,FALSE),0))*(MIN(IF(B3="Go AFK",IF(D3="",0,D3),0),'Rules & Formulas'!B13/60)*60)),0))*(IF((IFERROR(VLOOKUP(C3,Monsters!$T$4:$AH$15,8,FALSE),0))=0,0.35,IFERROR(VLOOKUP(C3,Monsters!$T$4:$AH$15,8,FALSE),0))/1)),MIN(('Rules & Formulas'!B15+25*AJ3),'Rules & Formulas'!B17)) | N3: =(1+0.08+0.12*AA3+0.12*AB3+0.16*AC3) | O3: =((AD3>=1)*1*(1+0.3*AE3)) | P3: =IF(OR(B3="Hunt",B3="Go AFK"),(('Rules & Formulas'!B4*(1+0.08)*('Rules & Formulas'!B5+0)*IFERROR(VLOOKUP(C3,Monsters!$T$4:$AH$15,10,FALSE),0)*IFERROR(VLOOKUP(C3,Monsters!$T$4:$AH$15,9,FALSE),0))*'Rules & Formulas'!B6),"") | Q3: =IF(OR(B3="Hunt",B3="Go AFK"),('Rules & Formulas'!B4*(1+0.08)*('Rules & Formulas'!B5+0)*IFERROR(VLOOKUP(C3,Monsters!$T$4:$AH$15,10,FALSE),0)*IFERROR(VLOOKUP(C3,Monsters!$T$4:$AH$15,9,FALSE),0)),"") | R3: =IF(AND((E3="OK"),B3="Hunt"),IF(B3="Hunt",(('Rules & Formulas'!B4*(1+0.08)*('Rules & Formulas'!B5+0)*IFERROR(VLOOKUP(C3,Monsters!$T$4:$AH$15,10,FALSE),0)*IFERROR(VLOOKUP(C3,Monsters!$T$4:$AH$15,9,FALSE),0))*'Rules & Formulas'!B6)*IF(D3="",0,D3),0),IF(AND((E3="OK"),B3="Go AFK"),IF(B3="Go AFK",MIN(IF((IF((IFERROR(VLOOKUP(C3,Monsters!$T$4:$AH$15,8,FALSE),0))=0,0.35,IFERROR(VLOOKUP(C3,Monsters!$T$4:$AH$15,8,FALSE),0))/1)<=0,999999,FLOOR(MIN('Rules & Formulas'!B15,'Rules & Formulas'!B17+'Rules & Formulas'!B14*(MIN(IF(B3="Go AFK",IF(D3="",0,D3),0),'Rules & Formulas'!B13/60)*60))/(IF((IFERROR(VLOOKUP(C3,Monsters!$T$4:$AH$15,8,FALSE),0))=0,0.35,IFERROR(VLOOKUP(C3,Monsters!$T$4:$AH$15,8,FALSE),0))/1),1)),('Rules & Formulas'!B4*(1+0.08)*('Rules & Formulas'!B5+0)*IFERROR(VLOOKUP(C3,Monsters!$T$4:$AH$15,10,FALSE),0)*IFERROR(VLOOKUP(C3,Monsters!$T$4:$AH$15,9,FALSE),0))*(MIN(IF(B3="Go AFK",IF(D3="",0,D3),0),'Rules & Formulas'!B13/60)*60)),0),0)) | S3: =(105/'Rules & Formulas'!B10)*'Rules & Formulas'!B11 | T3: =IF(0>=1,(MAX(1,ROUND('Rules & Formulas'!B18*(1+0.3*0)*(1+0.4*0),0)))*(1000/'Rules & Formulas'!B19)*MIN(0.95,'Rules & Formulas'!B20*SQRT(1+0.55*(0>=1))),0) | U3: =S3+T3 | V3: =IF(0>=IF((IFERROR(VLOOKUP(C3,Monsters!$T$4:$AH$15,15,FALSE),0))=0,120,IFERROR(VLOOKUP(C3,Monsters!$T$4:$AH$15,15,FALSE),0)),"YES","no") | W3: =IF(AND(B3="Fight boss",E3="OK"),IF((((105/'Rules & Formulas'!B10)*'Rules & Formulas'!B11+IF(0>=1,(MAX(1,ROUND('Rules & Formulas'!B18*(1+0.3*0)*(1+0.4*0),0)))*(1000/'Rules & Formulas'!B19)*MIN(0.95,'Rules & Formulas'!B20*SQRT(1+0.55*(0>=1))),0)))<=0,9999,(IFERROR(VLOOKUP(C3,Monsters!$T$4:$AH$15,2,FALSE),0))/(((105/'Rules & Formulas'!B10)*'Rules & Formulas'!B11+IF(0>=1,(MAX(1,ROUND('Rules & Formulas'!B18*(1+0.3*0)*(1+0.4*0),0)))*(1000/'Rules & Formulas'!B19)*MIN(0.95,'Rules & Formulas'!B20*SQRT(1+0.55*(0>=1))),0)))),"") | X3: =IF(AND(B3="Fight boss",E3="OK"),IF((IF((((105/'Rules & Formulas'!B10)*'Rules & Formulas'!B11+IF(0>=1,(MAX(1,ROUND('Rules & Formulas'!B18*(1+0.3*0)*(1+0.4*0),0)))*(1000/'Rules & Formulas'!B19)*MIN(0.95,'Rules & Formulas'!B20*SQRT(1+0.55*(0>=1))),0)))<=0,9999,(IFERROR(VLOOKUP(C3,Monsters!$T$4:$AH$15,2,FALSE),0))/(((105/'Rules & Formulas'!B10)*'Rules & Formulas'!B11+IF(0>=1,(MAX(1,ROUND('Rules & Formulas'!B18*(1+0.3*0)*(1+0.4*0),0)))*(1000/'Rules & Formulas'!B19)*MIN(0.95,'Rules & Formulas'!B20*SQRT(1+0.55*(0>=1))),0))))<='Rules & Formulas'!B12),"WIN","LOSE"),"") | Y3: =IF(B3="Go AFK",MIN(IF(B3="Go AFK",IF(D3="",0,D3),0),'Rules & Formulas'!B13/60),"") | Z3: =('Rules & Formulas'!B13+30*AI3) | AA3: =COUNTIFS($B$3:$B3,"Buy upgrade",$C$3:$C3,"Idle Power") | AB3: =COUNTIFS($B$3:$B3,"Buy upgrade",$C$3:$C3,"Iron Blade") | AC3: =COUNTIFS($B$3:$B3,"Buy upgrade",$C$3:$C3,"Steel Blade") | AD3: =COUNTIFS($B$3:$B3,"Hire hunter",$C$3:$C3,"Briar")+COUNTIFS($B$3:$B3,"Buy upgrade",$C$3:$C3,"Hire Briar") | AE3: =COUNTIFS($B$3:$B3,"Buy upgrade",$C$3:$C3,"Hunter Power") | AF3: =COUNTIFS($B$3:$B3,"Buy upgrade",$C$3:$C3,"Bigger Hits") | AG3: =COUNTIFS($B$3:$B3,"Buy upgrade",$C$3:$C3,"Swift Walk") | AH3: =COUNTIFS($B$3:$B3,"Buy upgrade",$C$3:$C3,"Loot Luck") | AI3: =COUNTIFS($B$3:$B3,"Buy upgrade",$C$3:$C3,"Offline Cap") | AJ3: =COUNTIFS($B$3:$B3,"Buy upgrade",$C$3:$C3,"Bigger Food Stock") | AK3: =COUNTIFS($B$3:$B3,"Buy upgrade",$C$3:$C3,"Food Efficiency")
A4: 2 | B4: Buy upgrade | C4: Iron Blade | E4: =IF(B4="","",IF(OR(B4="Hunt",B4="Go AFK"),IF(C4="","Can't","OK"),IF(B4="Fight boss",IF(I3<IF((IFERROR(VLOOKUP(C4,Monsters!$T$4:$AH$15,15,FALSE),0))=0,120,IFERROR(VLOOKUP(C4,Monsters!$T$4:$AH$15,15,FALSE),0)),"Can't","OK"),IF(B4="Hire hunter",IF(AND(C4="Briar",AD3>=1),"Can't",IF(H3<IF(C4="Briar",140,IF(C4="Quill",3650,IF(C4="Moss",4850,IF(C4="Ember",12200,0)))),"Can't","OK")),IF(OR(B4="Buy upgrade",B4="Forge/Scrapwork buy"),IF(IFERROR(VLOOKUP(C4,Upgrades!$N$4:$T$47,2,FALSE),0)="points","Can't",IF(IFERROR(VLOOKUP(C4,Upgrades!$N$4:$T$47,2,FALSE),0)="gold",IF(H3<IFERROR(FLOOR(IFERROR(VLOOKUP(C4,Upgrades!$N$4:$T$47,3,FALSE),0)*(IFERROR(VLOOKUP(C4,Upgrades!$N$4:$T$47,4,FALSE),0)^(COUNTIFS($B$3:$B3,"Buy upgrade",$C$3:$C3,C4)+COUNTIFS($B$3:$B3,"Hire hunter",$C$3:$C3,C4)+COUNTIFS($B$3:$B3,"Forge/Scrapwork buy",$C$3:$C3,C4))),1),0),"Can't","OK"),IF(IFERROR(VLOOKUP(C4,Upgrades!$N$4:$T$47,2,FALSE),0)="scraps",IF(J3<IFERROR(FLOOR(IFERROR(VLOOKUP(C4,Upgrades!$N$4:$T$47,3,FALSE),0)*(IFERROR(VLOOKUP(C4,Upgrades!$N$4:$T$47,4,FALSE),0)^(COUNTIFS($B$3:$B3,"Buy upgrade",$C$3:$C3,C4)+COUNTIFS($B$3:$B3,"Hire hunter",$C$3:$C3,C4)+COUNTIFS($B$3:$B3,"Forge/Scrapwork buy",$C$3:$C3,C4))),1),0),"Can't","OK"),IF(IFERROR(VLOOKUP(C4,Upgrades!$N$4:$T$47,2,FALSE),0)="mats","Can't","OK")))),"Check"))))) | F4: =IF(B4="","",IF(AND(B4="Fight boss",I3<IF((IFERROR(VLOOKUP(C4,Monsters!$T$4:$AH$15,15,FALSE),0))=0,120,IFERROR(VLOOKUP(C4,Monsters!$T$4:$AH$15,15,FALSE),0))),"Can't — need "&TEXT(IF((IFERROR(VLOOKUP(C4,Monsters!$T$4:$AH$15,15,FALSE),0))=0,120,IFERROR(VLOOKUP(C4,Monsters!$T$4:$AH$15,15,FALSE),0))-I3,"0.0")&" more Slayer points on the meter",IF(AND(B4="Hire hunter",C4="Briar",AD3>=1),"Can't — already hired",IF(AND(B4="Hire hunter",H3<IF(C4="Briar",140,IF(C4="Quill",3650,IF(C4="Moss",4850,IF(C4="Ember",12200,0))))),"Can't — need "&TEXT(IF(C4="Briar",140,IF(C4="Quill",3650,IF(C4="Moss",4850,IF(C4="Ember",12200,0))))-H3,"0")&" more gold",IF(AND(OR(B4="Buy upgrade",B4="Forge/Scrapwork buy"),IFERROR(VLOOKUP(C4,Upgrades!$N$4:$T$47,2,FALSE),0)="points"),"Can't — Sp-wallet spends not tracked here",IF(AND(OR(B4="Buy upgrade",B4="Forge/Scrapwork buy"),IFERROR(VLOOKUP(C4,Upgrades!$N$4:$T$47,2,FALSE),0)="gold",H3<IFERROR(FLOOR(IFERROR(VLOOKUP(C4,Upgrades!$N$4:$T$47,3,FALSE),0)*(IFERROR(VLOOKUP(C4,Upgrades!$N$4:$T$47,4,FALSE),0)^(COUNTIFS($B$3:$B3,"Buy upgrade",$C$3:$C3,C4)+COUNTIFS($B$3:$B3,"Hire hunter",$C$3:$C3,C4)+COUNTIFS($B$3:$B3,"Forge/Scrapwork buy",$C$3:$C3,C4))),1),0)),"Can't — need "&TEXT(IFERROR(FLOOR(IFERROR(VLOOKUP(C4,Upgrades!$N$4:$T$47,3,FALSE),0)*(IFERROR(VLOOKUP(C4,Upgrades!$N$4:$T$47,4,FALSE),0)^(COUNTIFS($B$3:$B3,"Buy upgrade",$C$3:$C3,C4)+COUNTIFS($B$3:$B3,"Hire hunter",$C$3:$C3,C4)+COUNTIFS($B$3:$B3,"Forge/Scrapwork buy",$C$3:$C3,C4))),1),0)-H3,"0")&" more gold",IF(AND(OR(B4="Buy upgrade",B4="Forge/Scrapwork buy"),IFERROR(VLOOKUP(C4,Upgrades!$N$4:$T$47,2,FALSE),0)="scraps",J3<IFERROR(FLOOR(IFERROR(VLOOKUP(C4,Upgrades!$N$4:$T$47,3,FALSE),0)*(IFERROR(VLOOKUP(C4,Upgrades!$N$4:$T$47,4,FALSE),0)^(COUNTIFS($B$3:$B3,"Buy upgrade",$C$3:$C3,C4)+COUNTIFS($B$3:$B3,"Hire hunter",$C$3:$C3,C4)+COUNTIFS($B$3:$B3,"Forge/Scrapwork buy",$C$3:$C3,C4))),1),0)),"Can't — need "&TEXT(IFERROR(FLOOR(IFERROR(VLOOKUP(C4,Upgrades!$N$4:$T$47,3,FALSE),0)*(IFERROR(VLOOKUP(C4,Upgrades!$N$4:$T$47,4,FALSE),0)^(COUNTIFS($B$3:$B3,"Buy upgrade",$C$3:$C3,C4)+COUNTIFS($B$3:$B3,"Hire hunter",$C$3:$C3,C4)+COUNTIFS($B$3:$B3,"Forge/Scrapwork buy",$C$3:$C3,C4))),1),0)-J3,"0")&" more scraps",IF(AND(B4="Fight boss",E4="OK",(IF((((105/'Rules & Formulas'!B10)*'Rules & Formulas'!B11+IF(AD3>=1,(MAX(1,ROUND('Rules & Formulas'!B18*(1+0.3*AE3)*(1+0.4*AF3),0)))*(1000/'Rules & Formulas'!B19)*MIN(0.95,'Rules & Formulas'!B20*SQRT(1+0.55*(AG3>=1))),0)))<=0,9999,(IFERROR(VLOOKUP(C4,Monsters!$T$4:$AH$15,2,FALSE),0))/(((105/'Rules & Formulas'!B10)*'Rules & Formulas'!B11+IF(AD3>=1,(MAX(1,ROUND('Rules & Formulas'!B18*(1+0.3*AE3)*(1+0.4*AF3),0)))*(1000/'Rules & Formulas'!B19)*MIN(0.95,'Rules & Formulas'!B20*SQRT(1+0.55*(AG3>=1))),0))))<='Rules & Formulas'!B12)),"WIN — boss down, next Level unlocks",IF(AND(B4="Fight boss",E4="OK"),"LOSE — TTK "&TEXT(IF((((105/'Rules & Formulas'!B10)*'Rules & Formulas'!B11+IF(AD3>=1,(MAX(1,ROUND('Rules & Formulas'!B18*(1+0.3*AE3)*(1+0.4*AF3),0)))*(1000/'Rules & Formulas'!B19)*MIN(0.95,'Rules & Formulas'!B20*SQRT(1+0.55*(AG3>=1))),0)))<=0,9999,(IFERROR(VLOOKUP(C4,Monsters!$T$4:$AH$15,2,FALSE),0))/(((105/'Rules & Formulas'!B10)*'Rules & Formulas'!B11+IF(AD3>=1,(MAX(1,ROUND('Rules & Formulas'!B18*(1+0.3*AE3)*(1+0.4*AF3),0)))*(1000/'Rules & Formulas'!B19)*MIN(0.95,'Rules & Formulas'!B20*SQRT(1+0.55*(AG3>=1))),0)))),"0")&"s > patience "&TEXT('Rules & Formulas'!B12,"0")&"s (leave resets HP)",IF(B4="Go AFK","AFK resolved (see AFK counted h)","Applied"))))))))) | G4: =IF(AND((E4="OK"),B4="Fight boss",(IF((((105/'Rules & Formulas'!B10)*'Rules & Formulas'!B11+IF(AD3>=1,(MAX(1,ROUND('Rules & Formulas'!B18*(1+0.3*AE3)*(1+0.4*AF3),0)))*(1000/'Rules & Formulas'!B19)*MIN(0.95,'Rules & Formulas'!B20*SQRT(1+0.55*(AG3>=1))),0)))<=0,9999,(IFERROR(VLOOKUP(C4,Monsters!$T$4:$AH$15,2,FALSE),0))/(((105/'Rules & Formulas'!B10)*'Rules & Formulas'!B11+IF(AD3>=1,(MAX(1,ROUND('Rules & Formulas'!B18*(1+0.3*AE3)*(1+0.4*AF3),0)))*(1000/'Rules & Formulas'!B19)*MIN(0.95,'Rules & Formulas'!B20*SQRT(1+0.55*(AG3>=1))),0))))<='Rules & Formulas'!B12),C4="Elder Thornpelt"),2,IF(AND((E4="OK"),B4="Fight boss",(IF((((105/'Rules & Formulas'!B10)*'Rules & Formulas'!B11+IF(AD3>=1,(MAX(1,ROUND('Rules & Formulas'!B18*(1+0.3*AE3)*(1+0.4*AF3),0)))*(1000/'Rules & Formulas'!B19)*MIN(0.95,'Rules & Formulas'!B20*SQRT(1+0.55*(AG3>=1))),0)))<=0,9999,(IFERROR(VLOOKUP(C4,Monsters!$T$4:$AH$15,2,FALSE),0))/(((105/'Rules & Formulas'!B10)*'Rules & Formulas'!B11+IF(AD3>=1,(MAX(1,ROUND('Rules & Formulas'!B18*(1+0.3*AE3)*(1+0.4*AF3),0)))*(1000/'Rules & Formulas'!B19)*MIN(0.95,'Rules & Formulas'!B20*SQRT(1+0.55*(AG3>=1))),0))))<='Rules & Formulas'!B12),C4="Ashfang Alpha"),3,G3)) | H4: =MAX(0,H3+IF(AND((E4="OK"),B4="Hunt"),(IF(B4="Hunt",(('Rules & Formulas'!B4*N3*('Rules & Formulas'!B5+O3)*IFERROR(VLOOKUP(C4,Monsters!$T$4:$AH$15,10,FALSE),0)*IFERROR(VLOOKUP(C4,Monsters!$T$4:$AH$15,9,FALSE),0))*'Rules & Formulas'!B6)*IF(D4="",0,D4),0))*(IFERROR(VLOOKUP(C4,Monsters!$T$4:$AH$15,3,FALSE),0))*(1+0.1*AH3)+(IF(OR(B4<>"Hunt",IFERROR(VLOOKUP(C4,Monsters!$T$4:$AH$15,6,FALSE),0)=0),0,FLOOR((IF(B4="Hunt",(('Rules & Formulas'!B4*N3*('Rules & Formulas'!B5+O3)*IFERROR(VLOOKUP(C4,Monsters!$T$4:$AH$15,10,FALSE),0)*IFERROR(VLOOKUP(C4,Monsters!$T$4:$AH$15,9,FALSE),0))*'Rules & Formulas'!B6)*IF(D4="",0,D4),0))/MAX(1,IFERROR(VLOOKUP(C4,Monsters!$T$4:$AH$15,6,FALSE),0)),1)))*(IFERROR(VLOOKUP(C4,Monsters!$T$4:$AH$15,7,FALSE),0))*0.5*(1+0.1*AH3),0)+IF(AND((E4="OK"),B4="Go AFK"),(IF(B4="Go AFK",MIN(IF((IF((IFERROR(VLOOKUP(C4,Monsters!$T$4:$AH$15,8,FALSE),0))=0,0.35,IFERROR(VLOOKUP(C4,Monsters!$T$4:$AH$15,8,FALSE),0))/(1+0.08*AK3))<=0,999999,FLOOR(MIN(('Rules & Formulas'!B15+25*AJ3),M3+('Rules & Formulas'!B14+0.4*AJ3)*(MIN(IF(B4="Go AFK",IF(D4="",0,D4),0),Z3/60)*60))/(IF((IFERROR(VLOOKUP(C4,Monsters!$T$4:$AH$15,8,FALSE),0))=0,0.35,IFERROR(VLOOKUP(C4,Monsters!$T$4:$AH$15,8,FALSE),0))/(1+0.08*AK3)),1)),('Rules & Formulas'!B4*N3*('Rules & Formulas'!B5+O3)*IFERROR(VLOOKUP(C4,Monsters!$T$4:$AH$15,10,FALSE),0)*IFERROR(VLOOKUP(C4,Monsters!$T$4:$AH$15,9,FALSE),0))*(MIN(IF(B4="Go AFK",IF(D4="",0,D4),0),Z3/60)*60)),0))*(IFERROR(VLOOKUP(C4,Monsters!$T$4:$AH$15,3,FALSE),0))*(1+0.1*AH3)+(IF(OR(B4<>"Go AFK",IFERROR(VLOOKUP(C4,Monsters!$T$4:$AH$15,6,FALSE),0)=0),0,FLOOR((IF(B4="Go AFK",MIN(IF((IF((IFERROR(VLOOKUP(C4,Monsters!$T$4:$AH$15,8,FALSE),0))=0,0.35,IFERROR(VLOOKUP(C4,Monsters!$T$4:$AH$15,8,FALSE),0))/(1+0.08*AK3))<=0,999999,FLOOR(MIN(('Rules & Formulas'!B15+25*AJ3),M3+('Rules & Formulas'!B14+0.4*AJ3)*(MIN(IF(B4="Go AFK",IF(D4="",0,D4),0),Z3/60)*60))/(IF((IFERROR(VLOOKUP(C4,Monsters!$T$4:$AH$15,8,FALSE),0))=0,0.35,IFERROR(VLOOKUP(C4,Monsters!$T$4:$AH$15,8,FALSE),0))/(1+0.08*AK3)),1)),('Rules & Formulas'!B4*N3*('Rules & Formulas'!B5+O3)*IFERROR(VLOOKUP(C4,Monsters!$T$4:$AH$15,10,FALSE),0)*IFERROR(VLOOKUP(C4,Monsters!$T$4:$AH$15,9,FALSE),0))*(MIN(IF(B4="Go AFK",IF(D4="",0,D4),0),Z3/60)*60)),0))/MAX(1,IFERROR(VLOOKUP(C4,Monsters!$T$4:$AH$15,6,FALSE),0)),1)))*(IFERROR(VLOOKUP(C4,Monsters!$T$4:$AH$15,7,FALSE),0))*0.5*(1+0.1*AH3),0)+IF(AND((E4="OK"),B4="Fight boss",(IF((((105/'Rules & Formulas'!B10)*'Rules & Formulas'!B11+IF(AD3>=1,(MAX(1,ROUND('Rules & Formulas'!B18*(1+0.3*AE3)*(1+0.4*AF3),0)))*(1000/'Rules & Formulas'!B19)*MIN(0.95,'Rules & Formulas'!B20*SQRT(1+0.55*(AG3>=1))),0)))<=0,9999,(IFERROR(VLOOKUP(C4,Monsters!$T$4:$AH$15,2,FALSE),0))/(((105/'Rules & Formulas'!B10)*'Rules & Formulas'!B11+IF(AD3>=1,(MAX(1,ROUND('Rules & Formulas'!B18*(1+0.3*AE3)*(1+0.4*AF3),0)))*(1000/'Rules & Formulas'!B19)*MIN(0.95,'Rules & Formulas'!B20*SQRT(1+0.55*(AG3>=1))),0))))<='Rules & Formulas'!B12)),IFERROR(VLOOKUP(C4,Monsters!$T$4:$AH$15,3,FALSE),0),0)-IF(AND((E4="OK"),OR(B4="Buy upgrade",B4="Forge/Scrapwork buy"),IFERROR(VLOOKUP(C4,Upgrades!$N$4:$T$47,2,FALSE),0)="gold"),IFERROR(FLOOR(IFERROR(VLOOKUP(C4,Upgrades!$N$4:$T$47,3,FALSE),0)*(IFERROR(VLOOKUP(C4,Upgrades!$N$4:$T$47,4,FALSE),0)^(COUNTIFS($B$3:$B3,"Buy upgrade",$C$3:$C3,C4)+COUNTIFS($B$3:$B3,"Hire hunter",$C$3:$C3,C4)+COUNTIFS($B$3:$B3,"Forge/Scrapwork buy",$C$3:$C3,C4))),1),0),0)-IF(AND((E4="OK"),B4="Hire hunter"),IF(C4="Briar",140,IF(C4="Quill",3650,IF(C4="Moss",4850,IF(C4="Ember",12200,0)))),0)) | I4: =IF(AND((E4="OK"),B4="Fight boss",(IF((((105/'Rules & Formulas'!B10)*'Rules & Formulas'!B11+IF(AD3>=1,(MAX(1,ROUND('Rules & Formulas'!B18*(1+0.3*AE3)*(1+0.4*AF3),0)))*(1000/'Rules & Formulas'!B19)*MIN(0.95,'Rules & Formulas'!B20*SQRT(1+0.55*(AG3>=1))),0)))<=0,9999,(IFERROR(VLOOKUP(C4,Monsters!$T$4:$AH$15,2,FALSE),0))/(((105/'Rules & Formulas'!B10)*'Rules & Formulas'!B11+IF(AD3>=1,(MAX(1,ROUND('Rules & Formulas'!B18*(1+0.3*AE3)*(1+0.4*AF3),0)))*(1000/'Rules & Formulas'!B19)*MIN(0.95,'Rules & Formulas'!B20*SQRT(1+0.55*(AG3>=1))),0))))<='Rules & Formulas'!B12)),0,MIN(IF(G3<=1,120,IF(G3=2,280,600)),I3+IF(AND((E4="OK"),B4="Hunt"),((IF(B4="Hunt",(('Rules & Formulas'!B4*N3*('Rules & Formulas'!B5+O3)*IFERROR(VLOOKUP(C4,Monsters!$T$4:$AH$15,10,FALSE),0)*IFERROR(VLOOKUP(C4,Monsters!$T$4:$AH$15,9,FALSE),0))*'Rules & Formulas'!B6)*IF(D4="",0,D4),0))*(IFERROR(VLOOKUP(C4,Monsters!$T$4:$AH$15,4,FALSE),0))+(IF(OR(B4<>"Hunt",IFERROR(VLOOKUP(C4,Monsters!$T$4:$AH$15,6,FALSE),0)=0),0,FLOOR((IF(B4="Hunt",(('Rules & Formulas'!B4*N3*('Rules & Formulas'!B5+O3)*IFERROR(VLOOKUP(C4,Monsters!$T$4:$AH$15,10,FALSE),0)*IFERROR(VLOOKUP(C4,Monsters!$T$4:$AH$15,9,FALSE),0))*'Rules & Formulas'!B6)*IF(D4="",0,D4),0))/MAX(1,IFERROR(VLOOKUP(C4,Monsters!$T$4:$AH$15,6,FALSE),0)),1)))*(IFERROR(VLOOKUP(C4,Monsters!$T$4:$AH$15,7,FALSE),0))),0)+IF(AND((E4="OK"),B4="Go AFK"),((IF(B4="Go AFK",MIN(IF((IF((IFERROR(VLOOKUP(C4,Monsters!$T$4:$AH$15,8,FALSE),0))=0,0.35,IFERROR(VLOOKUP(C4,Monsters!$T$4:$AH$15,8,FALSE),0))/(1+0.08*AK3))<=0,999999,FLOOR(MIN(('Rules & Formulas'!B15+25*AJ3),M3+('Rules & Formulas'!B14+0.4*AJ3)*(MIN(IF(B4="Go AFK",IF(D4="",0,D4),0),Z3/60)*60))/(IF((IFERROR(VLOOKUP(C4,Monsters!$T$4:$AH$15,8,FALSE),0))=0,0.35,IFERROR(VLOOKUP(C4,Monsters!$T$4:$AH$15,8,FALSE),0))/(1+0.08*AK3)),1)),('Rules & Formulas'!B4*N3*('Rules & Formulas'!B5+O3)*IFERROR(VLOOKUP(C4,Monsters!$T$4:$AH$15,10,FALSE),0)*IFERROR(VLOOKUP(C4,Monsters!$T$4:$AH$15,9,FALSE),0))*(MIN(IF(B4="Go AFK",IF(D4="",0,D4),0),Z3/60)*60)),0))*(IFERROR(VLOOKUP(C4,Monsters!$T$4:$AH$15,4,FALSE),0))+(IF(OR(B4<>"Go AFK",IFERROR(VLOOKUP(C4,Monsters!$T$4:$AH$15,6,FALSE),0)=0),0,FLOOR((IF(B4="Go AFK",MIN(IF((IF((IFERROR(VLOOKUP(C4,Monsters!$T$4:$AH$15,8,FALSE),0))=0,0.35,IFERROR(VLOOKUP(C4,Monsters!$T$4:$AH$15,8,FALSE),0))/(1+0.08*AK3))<=0,999999,FLOOR(MIN(('Rules & Formulas'!B15+25*AJ3),M3+('Rules & Formulas'!B14+0.4*AJ3)*(MIN(IF(B4="Go AFK",IF(D4="",0,D4),0),Z3/60)*60))/(IF((IFERROR(VLOOKUP(C4,Monsters!$T$4:$AH$15,8,FALSE),0))=0,0.35,IFERROR(VLOOKUP(C4,Monsters!$T$4:$AH$15,8,FALSE),0))/(1+0.08*AK3)),1)),('Rules & Formulas'!B4*N3*('Rules & Formulas'!B5+O3)*IFERROR(VLOOKUP(C4,Monsters!$T$4:$AH$15,10,FALSE),0)*IFERROR(VLOOKUP(C4,Monsters!$T$4:$AH$15,9,FALSE),0))*(MIN(IF(B4="Go AFK",IF(D4="",0,D4),0),Z3/60)*60)),0))/MAX(1,IFERROR(VLOOKUP(C4,Monsters!$T$4:$AH$15,6,FALSE),0)),1)))*(IFERROR(VLOOKUP(C4,Monsters!$T$4:$AH$15,7,FALSE),0))),0))) | J4: =MAX(0,J3+IF(AND((E4="OK"),B4="Hunt"),(IF(B4="Hunt",(('Rules & Formulas'!B4*N3*('Rules & Formulas'!B5+O3)*IFERROR(VLOOKUP(C4,Monsters!$T$4:$AH$15,10,FALSE),0)*IFERROR(VLOOKUP(C4,Monsters!$T$4:$AH$15,9,FALSE),0))*'Rules & Formulas'!B6)*IF(D4="",0,D4),0))*(IFERROR(VLOOKUP(C4,Monsters!$T$4:$AH$15,5,FALSE),0)),0)+IF(AND((E4="OK"),B4="Go AFK"),(IF(B4="Go AFK",MIN(IF((IF((IFERROR(VLOOKUP(C4,Monsters!$T$4:$AH$15,8,FALSE),0))=0,0.35,IFERROR(VLOOKUP(C4,Monsters!$T$4:$AH$15,8,FALSE),0))/(1+0.08*AK3))<=0,999999,FLOOR(MIN(('Rules & Formulas'!B15+25*AJ3),M3+('Rules & Formulas'!B14+0.4*AJ3)*(MIN(IF(B4="Go AFK",IF(D4="",0,D4),0),Z3/60)*60))/(IF((IFERROR(VLOOKUP(C4,Monsters!$T$4:$AH$15,8,FALSE),0))=0,0.35,IFERROR(VLOOKUP(C4,Monsters!$T$4:$AH$15,8,FALSE),0))/(1+0.08*AK3)),1)),('Rules & Formulas'!B4*N3*('Rules & Formulas'!B5+O3)*IFERROR(VLOOKUP(C4,Monsters!$T$4:$AH$15,10,FALSE),0)*IFERROR(VLOOKUP(C4,Monsters!$T$4:$AH$15,9,FALSE),0))*(MIN(IF(B4="Go AFK",IF(D4="",0,D4),0),Z3/60)*60)),0))*(IFERROR(VLOOKUP(C4,Monsters!$T$4:$AH$15,5,FALSE),0)),0)-IF(AND((E4="OK"),OR(B4="Buy upgrade",B4="Forge/Scrapwork buy"),IFERROR(VLOOKUP(C4,Upgrades!$N$4:$T$47,2,FALSE),0)="scraps"),IFERROR(FLOOR(IFERROR(VLOOKUP(C4,Upgrades!$N$4:$T$47,3,FALSE),0)*(IFERROR(VLOOKUP(C4,Upgrades!$N$4:$T$47,4,FALSE),0)^(COUNTIFS($B$3:$B3,"Buy upgrade",$C$3:$C3,C4)+COUNTIFS($B$3:$B3,"Hire hunter",$C$3:$C3,C4)+COUNTIFS($B$3:$B3,"Forge/Scrapwork buy",$C$3:$C3,C4))),1),0),0)) | K4: =MAX(0,K3+IF(AND((E4="OK"),B4="Hunt"),IF(C4="Thornpelt Bear",(IF(B4="Hunt",(('Rules & Formulas'!B4*N3*('Rules & Formulas'!B5+O3)*IFERROR(VLOOKUP(C4,Monsters!$T$4:$AH$15,10,FALSE),0)*IFERROR(VLOOKUP(C4,Monsters!$T$4:$AH$15,9,FALSE),0))*'Rules & Formulas'!B6)*IF(D4="",0,D4),0))*0.12,0),0)+IF(AND((E4="OK"),B4="Go AFK"),IF(C4="Thornpelt Bear",(IF(B4="Go AFK",MIN(IF((IF((IFERROR(VLOOKUP(C4,Monsters!$T$4:$AH$15,8,FALSE),0))=0,0.35,IFERROR(VLOOKUP(C4,Monsters!$T$4:$AH$15,8,FALSE),0))/(1+0.08*AK3))<=0,999999,FLOOR(MIN(('Rules & Formulas'!B15+25*AJ3),M3+('Rules & Formulas'!B14+0.4*AJ3)*(MIN(IF(B4="Go AFK",IF(D4="",0,D4),0),Z3/60)*60))/(IF((IFERROR(VLOOKUP(C4,Monsters!$T$4:$AH$15,8,FALSE),0))=0,0.35,IFERROR(VLOOKUP(C4,Monsters!$T$4:$AH$15,8,FALSE),0))/(1+0.08*AK3)),1)),('Rules & Formulas'!B4*N3*('Rules & Formulas'!B5+O3)*IFERROR(VLOOKUP(C4,Monsters!$T$4:$AH$15,10,FALSE),0)*IFERROR(VLOOKUP(C4,Monsters!$T$4:$AH$15,9,FALSE),0))*(MIN(IF(B4="Go AFK",IF(D4="",0,D4),0),Z3/60)*60)),0))*0.12,0),0)) | L4: =MAX(0,L3+IF(AND((E4="OK"),B4="Hunt"),IF(C4="Dire Thornpelt",(IF(B4="Hunt",(('Rules & Formulas'!B4*N3*('Rules & Formulas'!B5+O3)*IFERROR(VLOOKUP(C4,Monsters!$T$4:$AH$15,10,FALSE),0)*IFERROR(VLOOKUP(C4,Monsters!$T$4:$AH$15,9,FALSE),0))*'Rules & Formulas'!B6)*IF(D4="",0,D4),0))*0.1,0),0)+IF(AND((E4="OK"),B4="Go AFK"),IF(C4="Dire Thornpelt",(IF(B4="Go AFK",MIN(IF((IF((IFERROR(VLOOKUP(C4,Monsters!$T$4:$AH$15,8,FALSE),0))=0,0.35,IFERROR(VLOOKUP(C4,Monsters!$T$4:$AH$15,8,FALSE),0))/(1+0.08*AK3))<=0,999999,FLOOR(MIN(('Rules & Formulas'!B15+25*AJ3),M3+('Rules & Formulas'!B14+0.4*AJ3)*(MIN(IF(B4="Go AFK",IF(D4="",0,D4),0),Z3/60)*60))/(IF((IFERROR(VLOOKUP(C4,Monsters!$T$4:$AH$15,8,FALSE),0))=0,0.35,IFERROR(VLOOKUP(C4,Monsters!$T$4:$AH$15,8,FALSE),0))/(1+0.08*AK3)),1)),('Rules & Formulas'!B4*N3*('Rules & Formulas'!B5+O3)*IFERROR(VLOOKUP(C4,Monsters!$T$4:$AH$15,10,FALSE),0)*IFERROR(VLOOKUP(C4,Monsters!$T$4:$AH$15,9,FALSE),0))*(MIN(IF(B4="Go AFK",IF(D4="",0,D4),0),Z3/60)*60)),0))*0.1,0),0)) | M4: =IF(AND((E4="OK"),B4="Go AFK"),MAX(0,MIN(('Rules & Formulas'!B15+25*AJ3),M3+('Rules & Formulas'!B14+0.4*AJ3)*(MIN(IF(B4="Go AFK",IF(D4="",0,D4),0),Z3/60)*60))-(IF(B4="Go AFK",MIN(IF((IF((IFERROR(VLOOKUP(C4,Monsters!$T$4:$AH$15,8,FALSE),0))=0,0.35,IFERROR(VLOOKUP(C4,Monsters!$T$4:$AH$15,8,FALSE),0))/(1+0.08*AK3))<=0,999999,FLOOR(MIN(('Rules & Formulas'!B15+25*AJ3),M3+('Rules & Formulas'!B14+0.4*AJ3)*(MIN(IF(B4="Go AFK",IF(D4="",0,D4),0),Z3/60)*60))/(IF((IFERROR(VLOOKUP(C4,Monsters!$T$4:$AH$15,8,FALSE),0))=0,0.35,IFERROR(VLOOKUP(C4,Monsters!$T$4:$AH$15,8,FALSE),0))/(1+0.08*AK3)),1)),('Rules & Formulas'!B4*N3*('Rules & Formulas'!B5+O3)*IFERROR(VLOOKUP(C4,Monsters!$T$4:$AH$15,10,FALSE),0)*IFERROR(VLOOKUP(C4,Monsters!$T$4:$AH$15,9,FALSE),0))*(MIN(IF(B4="Go AFK",IF(D4="",0,D4),0),Z3/60)*60)),0))*(IF((IFERROR(VLOOKUP(C4,Monsters!$T$4:$AH$15,8,FALSE),0))=0,0.35,IFERROR(VLOOKUP(C4,Monsters!$T$4:$AH$15,8,FALSE),0))/(1+0.08*AK3))),MIN(('Rules & Formulas'!B15+25*AJ4),M3)) | N4: =(1+0.08+0.12*AA4+0.12*AB4+0.16*AC4) | O4: =((AD4>=1)*1*(1+0.3*AE4)) | P4: =IF(OR(B4="Hunt",B4="Go AFK"),(('Rules & Formulas'!B4*N3*('Rules & Formulas'!B5+O3)*IFERROR(VLOOKUP(C4,Monsters!$T$4:$AH$15,10,FALSE),0)*IFERROR(VLOOKUP(C4,Monsters!$T$4:$AH$15,9,FALSE),0))*'Rules & Formulas'!B6),"") | Q4: =IF(OR(B4="Hunt",B4="Go AFK"),('Rules & Formulas'!B4*N3*('Rules & Formulas'!B5+O3)*IFERROR(VLOOKUP(C4,Monsters!$T$4:$AH$15,10,FALSE),0)*IFERROR(VLOOKUP(C4,Monsters!$T$4:$AH$15,9,FALSE),0)),"") | R4: =IF(AND((E4="OK"),B4="Hunt"),IF(B4="Hunt",(('Rules & Formulas'!B4*N3*('Rules & Formulas'!B5+O3)*IFERROR(VLOOKUP(C4,Monsters!$T$4:$AH$15,10,FALSE),0)*IFERROR(VLOOKUP(C4,Monsters!$T$4:$AH$15,9,FALSE),0))*'Rules & Formulas'!B6)*IF(D4="",0,D4),0),IF(AND((E4="OK"),B4="Go AFK"),IF(B4="Go AFK",MIN(IF((IF((IFERROR(VLOOKUP(C4,Monsters!$T$4:$AH$15,8,FALSE),0))=0,0.35,IFERROR(VLOOKUP(C4,Monsters!$T$4:$AH$15,8,FALSE),0))/(1+0.08*AK3))<=0,999999,FLOOR(MIN(('Rules & Formulas'!B15+25*AJ3),M3+('Rules & Formulas'!B14+0.4*AJ3)*(MIN(IF(B4="Go AFK",IF(D4="",0,D4),0),Z3/60)*60))/(IF((IFERROR(VLOOKUP(C4,Monsters!$T$4:$AH$15,8,FALSE),0))=0,0.35,IFERROR(VLOOKUP(C4,Monsters!$T$4:$AH$15,8,FALSE),0))/(1+0.08*AK3)),1)),('Rules & Formulas'!B4*N3*('Rules & Formulas'!B5+O3)*IFERROR(VLOOKUP(C4,Monsters!$T$4:$AH$15,10,FALSE),0)*IFERROR(VLOOKUP(C4,Monsters!$T$4:$AH$15,9,FALSE),0))*(MIN(IF(B4="Go AFK",IF(D4="",0,D4),0),Z3/60)*60)),0),0)) | S4: =(105/'Rules & Formulas'!B10)*'Rules & Formulas'!B11 | T4: =IF(AD3>=1,(MAX(1,ROUND('Rules & Formulas'!B18*(1+0.3*AE3)*(1+0.4*AF3),0)))*(1000/'Rules & Formulas'!B19)*MIN(0.95,'Rules & Formulas'!B20*SQRT(1+0.55*(AG3>=1))),0) | U4: =S4+T4 | V4: =IF(I3>=IF((IFERROR(VLOOKUP(C4,Monsters!$T$4:$AH$15,15,FALSE),0))=0,120,IFERROR(VLOOKUP(C4,Monsters!$T$4:$AH$15,15,FALSE),0)),"YES","no") | W4: =IF(AND(B4="Fight boss",E4="OK"),IF((((105/'Rules & Formulas'!B10)*'Rules & Formulas'!B11+IF(AD3>=1,(MAX(1,ROUND('Rules & Formulas'!B18*(1+0.3*AE3)*(1+0.4*AF3),0)))*(1000/'Rules & Formulas'!B19)*MIN(0.95,'Rules & Formulas'!B20*SQRT(1+0.55*(AG3>=1))),0)))<=0,9999,(IFERROR(VLOOKUP(C4,Monsters!$T$4:$AH$15,2,FALSE),0))/(((105/'Rules & Formulas'!B10)*'Rules & Formulas'!B11+IF(AD3>=1,(MAX(1,ROUND('Rules & Formulas'!B18*(1+0.3*AE3)*(1+0.4*AF3),0)))*(1000/'Rules & Formulas'!B19)*MIN(0.95,'Rules & Formulas'!B20*SQRT(1+0.55*(AG3>=1))),0)))),"") | X4: =IF(AND(B4="Fight boss",E4="OK"),IF((IF((((105/'Rules & Formulas'!B10)*'Rules & Formulas'!B11+IF(AD3>=1,(MAX(1,ROUND('Rules & Formulas'!B18*(1+0.3*AE3)*(1+0.4*AF3),0)))*(1000/'Rules & Formulas'!B19)*MIN(0.95,'Rules & Formulas'!B20*SQRT(1+0.55*(AG3>=1))),0)))<=0,9999,(IFERROR(VLOOKUP(C4,Monsters!$T$4:$AH$15,2,FALSE),0))/(((105/'Rules & Formulas'!B10)*'Rules & Formulas'!B11+IF(AD3>=1,(MAX(1,ROUND('Rules & Formulas'!B18*(1+0.3*AE3)*(1+0.4*AF3),0)))*(1000/'Rules & Formulas'!B19)*MIN(0.95,'Rules & Formulas'!B20*SQRT(1+0.55*(AG3>=1))),0))))<='Rules & Formulas'!B12),"WIN","LOSE"),"") | Y4: =IF(B4="Go AFK",MIN(IF(B4="Go AFK",IF(D4="",0,D4),0),Z3/60),"") | Z4: =('Rules & Formulas'!B13+30*AI4) | AA4: =COUNTIFS($B$3:$B4,"Buy upgrade",$C$3:$C4,"Idle Power") | AB4: =COUNTIFS($B$3:$B4,"Buy upgrade",$C$3:$C4,"Iron Blade") | AC4: =COUNTIFS($B$3:$B4,"Buy upgrade",$C$3:$C4,"Steel Blade") | AD4: =COUNTIFS($B$3:$B4,"Hire hunter",$C$3:$C4,"Briar")+COUNTIFS($B$3:$B4,"Buy upgrade",$C$3:$C4,"Hire Briar") | AE4: =COUNTIFS($B$3:$B4,"Buy upgrade",$C$3:$C4,"Hunter Power") | AF4: =COUNTIFS($B$3:$B4,"Buy upgrade",$C$3:$C4,"Bigger Hits") | AG4: =COUNTIFS($B$3:$B4,"Buy upgrade",$C$3:$C4,"Swift Walk") | AH4: =COUNTIFS($B$3:$B4,"Buy upgrade",$C$3:$C4,"Loot Luck") | AI4: =COUNTIFS($B$3:$B4,"Buy upgrade",$C$3:$C4,"Offline Cap") | AJ4: =COUNTIFS($B$3:$B4,"Buy upgrade",$C$3:$C4,"Bigger Food Stock") | AK4: =COUNTIFS($B$3:$B4,"Buy upgrade",$C$3:$C4,"Food Efficiency")
